Workbook
Name MILLION: 'Input Sheet'!$C$9

Sheet Input Sheet
A1: Input Sheet
A2: Particulars | B2: Unit | D2: 1 | E2: =D2+1 -> 2 | F2: =E2+1 -> 3 | G2: =F2+1 -> 4 | H2: =G2+1 -> 5
A3: FY Ending | D3: =DATE(YEAR(C4)+IF(MONTH(C4)>3,1,0),3,31) -> 45382 | E3: =EDATE(D3,12) -> 45747 | F3: =EDATE(E3,12) -> 46112 | G3: =EDATE(F3,12) -> 46477 | H3: =EDATE(G3,12) -> 46843
A4: Date of commencement of business | B4: date | C4: 45017
A6: Croma sold appliances last year | B6: # | C6: =80+300+70+75+90+80 -> 695
A7: Croma wants to increase sales in next few years | B7: # | C7: 0.5
A9: Million | B9: #
A11: Average sales - croma dealers (Previous year)
A12: Washing machine | B12: num | C12: 80 | D12: =(ROUND(C12+(C12*$C$19),0))*12 -> 1104 | E12: =ROUND(D12+(D12*$C$19),0) -> 1270 | F12: =ROUND(E12+(E12*$C$19),0) -> 1461 | G12: =ROUND(F12+(F12*$C$19),0) -> 1680 | H12: =ROUND(G12+(G12*$C$19),0) -> 1932
A13: Mobile phone | B13: num | C13: 300 | D13: =(ROUND(C13+(C13*$C$19),0))*12 -> 4140 | E13: =ROUND(D13+(D13*$C$19),0) -> 4761 | F13: =ROUND(E13+(E13*$C$19),0) -> 5475 | G13: =ROUND(F13+(F13*$C$19),0) -> 6296 | H13: =ROUND(G13+(G13*$C$19),0) -> 7240
A14: T.V. | B14: num | C14: 70 | D14: =(ROUND(C14+(C14*$C$19),0))*12 -> 972 | E14: =ROUND(D14+(D14*$C$19),0) -> 1118 | F14: =ROUND(E14+(E14*$C$19),0) -> 1286 | G14: =ROUND(F14+(F14*$C$19),0) -> 1479 | H14: =ROUND(G14+(G14*$C$19),0) -> 1701
A15: Refrigerator | B15: num | C15: 75 | D15: =(ROUND(C15+(C15*$C$19),0))*12 -> 1032 | E15: =ROUND(D15+(D15*$C$19),0) -> 1187 | F15: =ROUND(E15+(E15*$C$19),0) -> 1365 | G15: =ROUND(F15+(F15*$C$19),0) -> 1570 | H15: =ROUND(G15+(G15*$C$19),0) -> 1806
A16: Laptop | B16: num | C16: 90 | D16: =(ROUND(C16+(C16*$C$19),0))*12 -> 1248 | E16: =ROUND(D16+(D16*$C$19),0) -> 1435 | F16: =ROUND(E16+(E16*$C$19),0) -> 1650 | G16: =ROUND(F16+(F16*$C$19),0) -> 1898 | H16: =ROUND(G16+(G16*$C$19),0) -> 2183
A17: A.C. | B17: num | C17: 80 | D17: =(ROUND(C17+(C17*$C$19),0))*12 -> 1104 | E17: =ROUND(D17+(D17*$C$19),0) -> 1270 | F17: =ROUND(E17+(E17*$C$19),0) -> 1461 | G17: =ROUND(F17+(F17*$C$19),0) -> 1680 | H17: =ROUND(G17+(G17*$C$19),0) -> 1932
A19: Sales growth rate | B19: % p.a. | C19: 0.15
A22: Prices
A23: Washing machine | B23: Rs. | C23: 12000 | D23: =ROUND(C23+(C23*$C$30),0) -> 12600 | E23: =ROUND(D23+(D23*$C$30),0) -> 13230 | F23: =ROUND(E23+(E23*$C$30),0) -> 13892 | G23: =ROUND(F23+(F23*$C$30),0) -> 14587 | H23: =ROUND(G23+(G23*$C$30),0) -> 15316
A24: Mobile phone | B24: Rs. | C24: 25000 | D24: =ROUND(C24+(C24*$C$30),0) -> 26250 | E24: =ROUND(D24+(D24*$C$30),0) -> 27563 | F24: =ROUND(E24+(E24*$C$30),0) -> 28941 | G24: =ROUND(F24+(F24*$C$30),0) -> 30388 | H24: =ROUND(G24+(G24*$C$30),0) -> 31907
A25: T.V. | B25: Rs. | C25: 35000 | D25: =ROUND(C25+(C25*$C$30),0) -> 36750 | E25: =ROUND(D25+(D25*$C$30),0) -> 38588 | F25: =ROUND(E25+(E25*$C$30),0) -> 40517 | G25: =ROUND(F25+(F25*$C$30),0) -> 42543 | H25: =ROUND(G25+(G25*$C$30),0) -> 44670
A26: Refrigerator | B26: Rs. | C26: 14000 | D26: =ROUND(C26+(C26*$C$30),0) -> 14700 | E26: =ROUND(D26+(D26*$C$30),0) -> 15435 | F26: =ROUND(E26+(E26*$C$30),0) -> 16207 | G26: =ROUND(F26+(F26*$C$30),0) -> 17017 | H26: =ROUND(G26+(G26*$C$30),0) -> 17868
A27: Laptop | B27: Rs. | C27: 40000 | D27: =ROUND(C27+(C27*$C$30),0) -> 42000 | E27: =ROUND(D27+(D27*$C$30),0) -> 44100 | F27: =ROUND(E27+(E27*$C$30),0) -> 46305 | G27: =ROUND(F27+(F27*$C$30),0) -> 48620 | H27: =ROUND(G27+(G27*$C$30),0) -> 51051
A28: A.C. | B28: Rs. | C28: 30000 | D28: =ROUND(C28+(C28*$C$30),0) -> 31500 | E28: =ROUND(D28+(D28*$C$30),0) -> 33075 | F28: =ROUND(E28+(E28*$C$30),0) -> 34729 | G28: =ROUND(F28+(F28*$C$30),0) -> 36465 | H28: =ROUND(G28+(G28*$C$30),0) -> 38288
A30: Price escalation | B30: % p.a. | C30: 0.05
A33: Sales amount
A34: Washing machine | B34: Rs. | C34: =C12*C23 -> 960000 | D34: =D12*D23 -> 13910400 | E34: =E12*E23 -> 16802100 | F34: =F12*F23 -> 20296212 | G34: =G12*G23 -> 24506160 | H34: =H12*H23 -> 29590512
A35: Mobile phone | B35: Rs. | C35: =C13*C24 -> 7500000 | D35: =D13*D24 -> 108675000 | E35: =E13*E24 -> 131227443 | F35: =F13*F24 -> 158451975 | G35: =G13*G24 -> 191322848 | H35: =H13*H24 -> 231006680
A36: T.V. | B36: Rs. | C36: =C14*C25 -> 2450000 | D36: =D14*D25 -> 35721000 | E36: =E14*E25 -> 43141384 | F36: =F14*F25 -> 52104862 | G36: =G14*G25 -> 62921097 | H36: =H14*H25 -> 75983670
A37: Refrigerator | B37: Rs. | C37: =C15*C26 -> 1050000 | D37: =D15*D26 -> 15170400 | E37: =E15*E26 -> 18321345 | F37: =F15*F26 -> 22122555 | G37: =G15*G26 -> 26716690 | H37: =H15*H26 -> 32269608
A38: Laptop | B38: Rs. | C38: =C16*C27 -> 3600000 | D38: =D16*D27 -> 52416000 | E38: =E16*E27 -> 63283500 | F38: =F16*F27 -> 76403250 | G38: =G16*G27 -> 92280760 | H38: =H16*H27 -> 111444333
A39: A.C. | B39: Rs. | C39: =C17*C28 -> 2400000 | D39: =D17*D28 -> 34776000 | E39: =E17*E28 -> 42005250 | F39: =F17*F28 -> 50739069 | G39: =G17*G28 -> 61261200 | H39: =H17*H28 -> 73972416
A40: Total Sales | C40: =SUM(C34:C39) -> 17960000 | D40: =SUM(D34:D39) -> 260668800 | E40: =SUM(E34:E39) -> 314781022 | F40: =SUM(F34:F39) -> 380117923 | G40: =SUM(G34:G39) -> 459008755 | H40: =SUM(H34:H39) -> 554267219
A42: Commission (revenue for franchisee)
A43: Washing machine | B43: % | C43: 0.25 | D43: =C43 -> 0.25 | E43: =D43 -> 0.25 | F43: =E43 -> 0.25 | G43: =F43 -> 0.25 | H43: =G43 -> 0.25
A44: Mobile phone | B44: % | C44: 0.15 | D44: =C44 -> 0.15 | E44: =D44 -> 0.15 | F44: =E44 -> 0.15 | G44: =F44 -> 0.15 | H44: =G44 -> 0.15
A45: T.V. | B45: % | C45: 0.2 | D45: =C45 -> 0.2 | E45: =D45 -> 0.2 | F45: =E45 -> 0.2 | G45: =F45 -> 0.2 | H45: =G45 -> 0.2
A46: Refrigerator | B46: % | C46: 0.2 | D46: =C46 -> 0.2 | E46: =D46 -> 0.2 | F46: =E46 -> 0.2 | G46: =F46 -> 0.2 | H46: =G46 -> 0.2
A47: Laptop | B47: % | C47: 0.18 | D47: =C47 -> 0.18 | E47: =D47 -> 0.18 | F47: =E47 -> 0.18 | G47: =F47 -> 0.18 | H47: =G47 -> 0.18
A48: A.C. | B48: % | C48: 0.15 | D48: =C48 -> 0.15 | E48: =D48 -> 0.15 | F48: =E48 -> 0.15 | G48: =F48 -> 0.15 | H48: =G48 -> 0.15
A50: Dealear requirements (Area in sq.ft)
A51: Showroom | B51: sq.ft. | C51: 12000 | D51: =C51 -> 12000 | E51: =D51 -> 12000 | F51: =E51 -> 12000 | G51: =F51 -> 12000 | H51: =G51 -> 12000
...

Sheet AS
A1: Fixed Asset Schedule
A2: Particulars | B2: Unit | C2: 1 | D2: =C2+1 -> 2 | E2: =D2+1 -> 3 | F2: =E2+1 -> 4 | G2: =F2+1 -> 5
A3: FY Ending | C3: ='Input Sheet'!D3 -> 45382 | D3: ='Input Sheet'!E3 -> 45747 | E3: ='Input Sheet'!F3 -> 46112 | F3: ='Input Sheet'!G3 -> 46477 | G3: ='Input Sheet'!H3 -> 46843
A4: Asset schedule
A6: Opening balance | B6: Rs. | C6: ='Input Sheet'!C88 -> 20000000 | D6: =C9 -> 17600000 | E6: =D9 -> 15488000 | F6: =E9 -> 13629440 | G6: =F9 -> 11993907
A7: Add: Capex | B7: Rs. | C7: 0 | D7: =C10 -> 0 | E7: =D10 -> 0 | F7: =E10 -> 0 | G7: =F10 -> 0
A8: Less: Depreciation | B8: Rs. | C8: =C6*'Input Sheet'!$C$79 -> 2400000 | D8: =D6*'Input Sheet'!$C$79 -> 2112000 | E8: =E6*'Input Sheet'!$C$79 -> 1858560 | F8: =F6*'Input Sheet'!$C$79 -> 1635532.8 | G8: =G6*'Input Sheet'!$C$79 -> 1439268.9
A9: Closing balance | B9: Rs. | C9: =C6+C7-C8 -> 17600000 | D9: =D6+D7-D8 -> 15488000 | E9: =E6+E7-E8 -> 13629440 | F9: =F6+F7-F8 -> 11993907 | G9: =G6+G7-G8 -> 10554638
A12: End of sheet

Sheet DS
A1: Debt Schedule
A2: Particulars | B2: Unit | D2: 1 | E2: =D2+1 -> 2 | F2: =E2+1 -> 3 | G2: =F2+1 -> 4 | H2: =G2+1 -> 5
A3: FY Ending | D3: =AS!C3 -> 45382 | E3: =AS!D3 -> 45747 | F3: =AS!E3 -> 46112 | G3: =AS!F3 -> 46477 | H3: =AS!G3 -> 46843
A4: Debt schedule
A6: Opening balance | B6: Rs. | D6: ='Input Sheet'!C102 -> 16064000 | E6: =D9 -> 13633781 | F6: =E9 -> 10863332 | G6: =F9 -> 7705019.1 | H6: =G9 -> 4104542.9
A7: Add: Debt drawdown | B7: Rs. | D7: 0 | E7: 0 | F7: 0 | G7: 0 | H7: 0
A8: Less: Debt repaid | B8: Rs. | D8: =I18 -> 2430218.9 | E8: =I19 -> 2770449.5 | F8: =I20 -> 3158312.5 | G8: =I21 -> 3600476.2 | H8: =J21 -> 4104542.9
A9: Closing balance | B9: Rs. | D9: =D6+D7-D8 -> 13633781 | E9: =E6+E7-E8 -> 10863332 | F9: =F6+F7-F8 -> 7705019.1 | G9: =G6+G7-G8 -> 4104542.9 | H9: =H6+H7-H8 -> 0
D14: EMI (Annual)
D16: Debt Repayment Schedule
D17: S.No. | E17: Year starting from | F17: Opening balance | G17: EMI | H17: Interest | I17: Principle | J17: Closing balance
D18: 1 | F18: =D6 -> 16064000 | G18: =PMT(14%,5,-F18) -> 4679178.9 | H18: =F18*'Input Sheet'!$C$95 -> 2248960 | I18: =G18-H18 -> 2430218.9 | J18: =F18-I18 -> 13633781
D19: =D18+1 -> 2 | F19: =J18 -> 13633781 | G19: =G18 -> 4679178.9 | H19: =F19*'Input Sheet'!$C$95 -> 1908729.4 | I19: =G19-H19 -> 2770449.5 | J19: =F19-I19 -> 10863332
D20: =D19+1 -> 3 | F20: =J19 -> 10863332 | G20: =G19 -> 4679178.9 | H20: =F20*'Input Sheet'!$C$95 -> 1520866.4 | I20: =G20-H20 -> 3158312.5 | J20: =F20-I20 -> 7705019.1
D21: =D20+1 -> 4 | F21: =J20 -> 7705019.1 | G21: =G20 -> 4679178.9 | H21: =F21*'Input Sheet'!$C$95 -> 1078702.7 | I21: =G21-H21 -> 3600476.2 | J21: =F21-I21 -> 4104542.9
D22: =D21+1 -> 5 | F22: =J21 -> 4104542.9 | G22: =G21 -> 4679178.9 | H22: =F22*'Input Sheet'!$C$95 -> 574636 | I22: =G22-H22 -> 4104542.9 | J22: =F22-I22 -> 0
A25: End of sheet

Sheet P&L
A1: Income Statement
A2: Particulars | B2: Unit | D2: 1 | E2: =D2+1 -> 2 | F2: =E2+1 -> 3 | G2: =F2+1 -> 4 | H2: =G2+1 -> 5
A3: FY Ending | D3: ='Input Sheet'!D3 -> 45382 | E3: ='Input Sheet'!E3 -> 45747 | F3: ='Input Sheet'!F3 -> 46112 | G3: ='Input Sheet'!G3 -> 46477 | H3: ='Input Sheet'!H3 -> 46843
A4: Revenues
A5: Washing machine | B5: Rs. | D5: ='Input Sheet'!D34*'Input Sheet'!$C$43 -> 3477600 | E5: ='Input Sheet'!E34*'Input Sheet'!$C$43 -> 4200525 | F5: ='Input Sheet'!F34*'Input Sheet'!$C$43 -> 5074053 | G5: ='Input Sheet'!G34*'Input Sheet'!$C$43 -> 6126540 | H5: ='Input Sheet'!H34*'Input Sheet'!$C$43 -> 7397628
A6: Mobile phone | B6: Rs. | D6: ='Input Sheet'!D35*'Input Sheet'!$C$44 -> 16301250 | E6: ='Input Sheet'!E35*'Input Sheet'!$C$44 -> 19684116 | F6: ='Input Sheet'!F35*'Input Sheet'!$C$44 -> 23767796 | G6: ='Input Sheet'!G35*'Input Sheet'!$C$44 -> 28698427 | H6: ='Input Sheet'!H35*'Input Sheet'!$C$44 -> 34651002
A7: T.V. | B7: Rs. | D7: ='Input Sheet'!D36*'Input Sheet'!$C$45 -> 7144200 | E7: ='Input Sheet'!E36*'Input Sheet'!$C$45 -> 8628276.8 | F7: ='Input Sheet'!F36*'Input Sheet'!$C$45 -> 10420972 | G7: ='Input Sheet'!G36*'Input Sheet'!$C$45 -> 12584219 | H7: ='Input Sheet'!H36*'Input Sheet'!$C$45 -> 15196734
A8: Refrigerator | B8: Rs. | D8: ='Input Sheet'!D37*'Input Sheet'!$C$46 -> 3034080 | E8: ='Input Sheet'!E37*'Input Sheet'!$C$46 -> 3664269 | F8: ='Input Sheet'!F37*'Input Sheet'!$C$46 -> 4424511 | G8: ='Input Sheet'!G37*'Input Sheet'!$C$46 -> 5343338 | H8: ='Input Sheet'!H37*'Input Sheet'!$C$46 -> 6453921.6
A9: Laptop | B9: Rs. | D9: ='Input Sheet'!D38*'Input Sheet'!$C$47 -> 9434880 | E9: ='Input Sheet'!E38*'Input Sheet'!$C$47 -> 11391030 | F9: ='Input Sheet'!F38*'Input Sheet'!$C$47 -> 13752585 | G9: ='Input Sheet'!G38*'Input Sheet'!$C$47 -> 16610537 | H9: ='Input Sheet'!H38*'Input Sheet'!$C$47 -> 20059980
A10: A.C. | B10: Rs. | D10: ='Input Sheet'!D39*'Input Sheet'!$C$48 -> 5216400 | E10: ='Input Sheet'!E39*'Input Sheet'!$C$48 -> 6300787.5 | F10: ='Input Sheet'!F39*'Input Sheet'!$C$48 -> 7610860.3 | G10: ='Input Sheet'!G39*'Input Sheet'!$C$48 -> 9189180 | H10: ='Input Sheet'!H39*'Input Sheet'!$C$48 -> 11095862
A11: Total revenues | B11: Rs. | D11: =SUM(D5:D10) -> 44608410 | E11: =SUM(E5:E10) -> 53869005 | F11: =SUM(F5:F10) -> 65050778 | G11: =SUM(G5:G10) -> 78552241 | H11: =SUM(H5:H10) -> 94855128
A13: Operating expenses
A14: Salaries | B14: Rs. | D14: ='Input Sheet'!D65 -> 7433856 | E14: ='Input Sheet'!E65 -> 9634277.4 | F14: ='Input Sheet'!F65 -> 12486023 | G14: ='Input Sheet'!G65 -> 16181886 | H14: ='Input Sheet'!H65 -> 20971725
A15: Rent - Showroom | B15: Rs. | D15: ='Input Sheet'!D75 -> 12326400 | E15: ='Input Sheet'!E75 -> 13189248 | F15: ='Input Sheet'!F75 -> 14112495 | G15: ='Input Sheet'!G75 -> 15100370 | H15: ='Input Sheet'!H75 -> 16157396
A16: Rent - Go-down | B16: Rs. | D16: ='Input Sheet'!D76 -> 9244800 | E16: ='Input Sheet'!E76 -> 9891936 | F16: ='Input Sheet'!F76 -> 10584372 | G16: ='Input Sheet'!G76 -> 11325278 | H16: ='Input Sheet'!H76 -> 12118047
A17: Additional operating expenses | B17: Rs. | D17: =D11*'Input Sheet'!$C$81 -> 8921682 | E17: =E11*'Input Sheet'!$C$81 -> 10773801 | F17: =F11*'Input Sheet'!$C$81 -> 13010156 | G17: =G11*'Input Sheet'!$C$81 -> 15710448 | H17: =H11*'Input Sheet'!$C$81 -> 18971026
A18: Total operating expenses | B18: Rs. | D18: =SUM(D14:D17) -> 37926738 | E18: =SUM(E14:E17) -> 43489262 | F18: =SUM(F14:F17) -> 50193046 | G18: =SUM(G14:G17) -> 58317982 | H18: =SUM(H14:H17) -> 68218193
A20: EBITDA | B20: Rs. | D20: =D11-D18 -> 6681672 | E20: =E11-E18 -> 10379742 | F20: =F11-F18 -> 14857732 | G20: =G11-G18 -> 20234259 | H20: =H11-H18 -> 26636935
A21: Less: D&A | B21: Rs. | D21: =AS!C8 -> 2400000 | E21: =AS!D8 -> 2112000 | F21: =AS!E8 -> 1858560 | G21: =AS!F8 -> 1635532.8 | H21: =AS!G8 -> 1439268.9
A23: EBIT | B23: Rs. | D23: =D20-D21 -> 4281672 | E23: =E20-E21 -> 8267742.4 | F23: =F20-F21 -> 12999172 | G23: =G20-G21 -> 18598726 | H23: =H20-H21 -> 25197666
A24: Less: Interest | B24: Rs. | D24: =DS!H18 -> 2248960 | E24: =DS!H19 -> 1908729.4 | F24: =DS!H20 -> 1520866.4 | G24: =DS!H21 -> 1078702.7 | H24: =DS!H22 -> 574636
A26: EBT | B26: Rs. | D26: =D23-D24 -> 2032712 | E26: =E23-E24 -> 6359013.1 | F26: =F23-F24 -> 11478306 | G26: =G23-G24 -> 17520024 | H26: =H23-H24 -> 24623030
A27: Less: Income tax | B27: Rs. | D27: =D26*30% -> 609813.6 | E27: =E26*30% -> 1907703.9 | F27: =F26*30% -> 3443491.7 | G27: =G26*30% -> 5256007.1 | H27: =H26*30% -> 7386908.9
A29: EAT | B29: Rs. | D29: =D26-D27 -> 1422898.4 | E29: =E26-E27 -> 4451309.1 | F29: =F26-F27 -> 8034813.9 | G29: =G26-G27 -> 12264017 | H29: =H26-H27 -> 17236121
A32: End of sheet

Sheet BS
A1: Balance Sheet
A2: Particulars | B2: Unit | D2: 1 | E2: =D2+1 -> 2 | F2: =E2+1 -> 3 | G2: =F2+1 -> 4 | H2: =G2+1 -> 5
A3: FY Ending | D3: ='Input Sheet'!D3 -> 45382 | E3: ='Input Sheet'!E3 -> 45747 | F3: ='Input Sheet'!F3 -> 46112 | G3: ='Input Sheet'!G3 -> 46477 | H3: ='Input Sheet'!H3 -> 46843
A4: Assets
A5: Cash | B5: Rs. | D5: =CFS!D23 -> 3641639.5 | E5: =CFS!E23 -> 5701589 | F5: =CFS!F23 -> 8255927.9 | G5: =CFS!G23 -> 11377776 | H5: =CFS!H23 -> 15145483
A6: Fixed assets | B6: Rs. | D6: =AS!C9+'P&L'!D15+'P&L'!D16 -> 39171200 | E6: =AS!D9+'P&L'!E15+'P&L'!E16 -> 38569184 | F6: =AS!E9+'P&L'!F15+'P&L'!F16 -> 38326307 | G6: =AS!F9+'P&L'!G15+'P&L'!G16 -> 38419555 | H6: =AS!G9+'P&L'!H15+'P&L'!H16 -> 38830081
A8: Total assets | B8: Rs | D8: =SUM(D5:D7) -> 42812840 | E8: =SUM(E5:E7) -> 44270773 | F8: =SUM(F5:F7) -> 46582235 | G8: =SUM(G5:G7) -> 49797331 | H8: =SUM(H5:H7) -> 53975564
A11: Liabilities
A12: Equity | D12: ='Input Sheet'!C101 -> 24096000 | E12: =D12 -> 24096000 | F12: =E12 -> 24096000 | G12: =F12 -> 24096000 | H12: =G12 -> 24096000
A13: Reserves & surplus | D13: ='P&L'!D29+3660160 -> 5083058.4 | E13: ='P&L'!E29+4860132.24611562 -> 9311441.4 | F13: ='P&L'!F29+6746401.72668743 -> 14781216 | G13: ='P&L'!G29+9332771.1329393 -> 21596788 | H13: ='P&L'!H29+12643443.2083544 -> 29879564
A14: Debt | B14: Rs. | D14: =DS!D9 -> 13633781 | E14: =DS!E9 -> 10863332 | F14: =DS!F9 -> 7705019.1 | G14: =DS!G9 -> 4104542.9 | H14: =DS!H9 -> 0
A16: Total liabilities | B16: Rs. | D16: =D12+D13+D14 -> 42812840 | E16: =E12+E13+E14 -> 44270773 | F16: =F12+F13+F14 -> 46582235 | G16: =G12+G13+G14 -> 49797331 | H16: =H12+H13+H14 -> 53975564
A19: Checksum | B19: Rs. | D19: =D16-D8 -> 0 | E19: =E16-E8 -> 0 | F19: =F16-F8 -> 0 | G19: =G16-G8 -> 0 | H19: =H16-H8 -> 0
A22: End of sheet

Sheet CFS
A1: Cash Flow Statement
A2: Particulars | B2: Unit | D2: 1 | E2: =D2+1 -> 2 | F2: =E2+1 -> 3 | G2: =F2+1 -> 4 | H2: =G2+1 -> 5
A3: FY Ending | D3: ='Input Sheet'!D3 -> 45382 | E3: ='Input Sheet'!E3 -> 45747 | F3: ='Input Sheet'!F3 -> 46112 | G3: ='Input Sheet'!G3 -> 46477 | H3: ='Input Sheet'!H3 -> 46843
A5: Cash flow from operating activities
A6: EAT (Net Income) | B6: Rs. | D6: ='P&L'!D29 -> 1422898.4 | E6: ='P&L'!E29 -> 4451309.1 | F6: ='P&L'!F29 -> 8034813.9 | G6: ='P&L'!G29 -> 12264017 | H6: ='P&L'!H29 -> 17236121
A7: Add: D&A | B7: Rs. | D7: =AS!C8 -> 2400000 | E7: =AS!D8 -> 2112000 | F7: =AS!E8 -> 1858560 | G7: =AS!F8 -> 1635532.8 | H7: =AS!G8 -> 1439268.9
A8: Add: Interest | B8: Rs. | D8: ='P&L'!D24 -> 2248960 | E8: ='P&L'!E24 -> 1908729.4 | F8: ='P&L'!F24 -> 1520866.4 | G8: ='P&L'!G24 -> 1078702.7 | H8: ='P&L'!H24 -> 574636
A9: Cash flow/used from operating activities | B9: Rs. | D9: =SUM(D6:D8) -> 6071858.4 | E9: =SUM(E6:E8) -> 8472038.5 | F9: =SUM(F6:F8) -> 11414240 | G9: =SUM(G6:G8) -> 14978252 | H9: =SUM(H6:H8) -> 19250026
A11: Cash flow from investing activities
A12: Fixed asset (capex) | B12: Rs. | D12: 0 | E12: 0 | F12: 0 | G12: 0 | H12: 0
A13: Cash flow from investing activities | D13: 0 | E13: 0 | F13: 0 | G13: 0 | H13: 0
A15: Cash flow from financing activities
A16: Equity | B16: Rs. | D16: 0 | E16: 0 | F16: 0 | G16: 0 | H16: 0
A17: Add: debt adjustments | B17: Rs. | D17: 0 | E17: 0 | F17: 0 | G17: 0 | H17: 0
A18: Less: Interest | B18: Rs. | D18: =-DS!D8 -> -2430218.9 | E18: =-DS!E8 -> -2770449.5 | F18: =-DS!F8 -> -3158312.5 | G18: =-DS!G8 -> -3600476.2 | H18: =-DS!H8 -> -4104542.9
A19: Cash flow/used from financing activites | B19: Rs. | D19: =SUM(D16:D18) -> -2430218.9 | E19: =SUM(E16:E18) -> -2770449.5 | F19: =SUM(F16:F18) -> -3158312.5 | G19: =SUM(G16:G18) -> -3600476.2 | H19: =SUM(H16:H18) -> -4104542.9
A21: Net cash flow/used during the year | B21: Rs.
A22: Add: Opening balance of cash | B22: Rs. | D22: 0 | E22: 0 | F22: 0 | G22: 0 | H22: 0
A23: Closing balance of cash | B23: Rs. | D23: =D9+D13+D19+D22 -> 3641639.5 | E23: =E9+E13+E19+E22 -> 5701589 | F23: =F9+F13+F19+F22 -> 8255927.9 | G23: =G9+G13+G19+G22 -> 11377776 | H23: =H9+H13+H19+H22 -> 15145483
A26: End of sheet

Sheet Viability Analysis
A1: Particulars | B1: Unit | C1: 0 | D1: 1 | E1: =D1+1 -> 2 | F1: =E1+1 -> 3 | G1: =F1+1 -> 4 | H1: =G1+1 -> 5
A2: FY Ending | C2: ='Input Sheet'!C4 -> 45017 | D2: ='Input Sheet'!D3 -> 45382 | E2: ='Input Sheet'!E3 -> 45747 | F2: ='Input Sheet'!F3 -> 46112 | G2: ='Input Sheet'!G3 -> 46477 | H2: ='Input Sheet'!H3 -> 46843
A4: Net Profit | D4: ='P&L'!D29 -> 1422898.4 | E4: ='P&L'!E29 -> 4451309.1 | F4: ='P&L'!F29 -> 8034813.9 | G4: ='P&L'!G29 -> 12264017 | H4: ='P&L'!H29 -> 17236121
A5: Add: depreciation | D5: =AS!C8 -> 2400000 | E5: =AS!D8 -> 2112000 | F5: =AS!E8 -> 1858560 | G5: =AS!F8 -> 1635532.8 | H5: =AS!G8 -> 1439268.9
A6: Less: Initial Investment (Capital expenses) | D6: 0 | E6: 0 | F6: 0 | G6: 0 | H6: 0
A7: Add/less: Debt amount raised / (repaid) | D7: =DS!D8 -> 2430218.9 | E7: =DS!E8 -> 2770449.5 | F7: =DS!F8 -> 3158312.5 | G7: =DS!G8 -> 3600476.2 | H7: =DS!H8 -> 4104542.9
A8: Add: Security deposit refund | D8: 0 | E8: 0 | F8: 0 | G8: 0 | H8: 0
A9: Free Cash flows | C9: =-'Input Sheet'!C101 -> -24096000 | D9: =D4+D5-D6-D7+D8 -> 1392679.5 | E9: =E4+E5-E6-E7+E8 -> 3792859.6 | F9: =F4+F5-F6-F7+F8 -> 6735061.5 | G9: =G4+G5-G6-G7+G8 -> 10299073 | H9: =H4+H5-H6-H7+H8 -> 14570847
A10: IRR | B10: =IRR(C9:H9) -> 0.11723158
A11: NPV | B11: =NPV(B13,D9:H9)+C9 -> -5581442.1
A13: Hurdle rate/Cost of equity | B13: 0.2
A15: Since NPV is Negative, the business doesn't seem viable for Mr. Sonu
