Workbook
Name \a: #REF!
Name \a: #REF!
Name \b: #REF!
Name \b: #REF!
Name _ACC1: #REF!
Name _ADD1: #REF!
Name _ADD2: #REF!
Name _ADD3: #REF!
Name _CAP1: #REF!
Name _CAP2: #REF!
Name _CAP3: #REF!
Name _dcc4: #REF!
Name _IRR1: #REF!
Name _IRR2: #REF!
Name _IRR3: #REF!
Name _IRR4: #REF!
Name _IRR5: #REF!
Name _IRR6: #REF!
Name _Mei97: #REF!
Name _NO1: #REF!
Name _NO2: #REF!
Name _NO3: #REF!
Name _NO4: #REF!
Name _NO5: #REF!
Name _NO6: #REF!
Name _NO7: #REF!
Name _RAN1: #REF!
Name _RAN2: #REF!
Name _RAN3: #REF!
Name _tb2: #REF!
Name a_case: #REF!
Name aaa: #REF!
Name aaaa: #REF!
Name aaaaaaaaaa: #REF!
Name aaaaaaaaaaa: #REF!
Name aaaaaaaaaaaaaarrrrrrrrr: #REF!
Name aaaaaaaaassssssssssssssshhhh: #REF!
Name aashi: #REF!
Name abc: {17}
Name abc: {17}
Name abc: {17}
Name abc: {17}
Name abc: {17}
Name abc: {17}
Name abc: {17}
Name abc: {17}
Name abcd: #REF!
Name AC: #REF!
Name ACapital: #REF!
Name ACapital: #REF!
Name AcqData: #REF!
Name AcqData2: #REF!
Name ADD: #REF!
Name ADR_SWITCH: #REF!
Name AllTables: {17}
Name AllTables: {17}
Name AllTables: {17}
Name AllTables: {17}
Name AllTables: {17}
Name AllTables: {17}

Sheet Charts
E2: Charts | L2: USD | M2: lacs
L3: INR | M3: Crore
L4: AED | M4: Million
E6: Revenue & Profitability | L6: AED | M6: Million
A7: AED | E7: AED | F7: Million | I7: AED | J7: Million
E26: Cash Analysis & Balance Sheet
R30: =E26 -> Cash Analysis & Balance Sheet | S30: =Dashboard!D5 -> 25-26 | T30: =Dashboard!E5 -> 26-27 | U30: =Dashboard!F5 -> 27-28 | V30: =Dashboard!G5 -> 28-29 | W30: =Dashboard!H5 -> 29-30
R31: Cash Burn/Cash Saving | S31: =Dashboard!D29 -> 2737.6442 | T31: =Dashboard!E29 -> -36.440992 | U31: =Dashboard!F29 -> 352.5965 | V31: =Dashboard!G29 -> 677.84776 | W31: =Dashboard!H29 -> 1052.7073
R32: Ending Cash Balance | S32: =Dashboard!D30 -> 2738.0139 | T32: =Dashboard!E30 -> 2701.5729 | U32: =Dashboard!F30 -> 3054.1694 | V32: =Dashboard!G30 -> 3732.0171 | W32: =Dashboard!H30 -> 4784.7245
E44: Funding Requirement
B46: Total Funds Requirement | E46: =Config!C30 -> 300 | G46: Funds Utilization
B47: Valuation | E47: =Dashboard!D36 -> 2724.0294 | J47: =$E$46*I47 -> 0
B48: Equity Dilution | E48: =E46/E47 -> 0.11013097 | J48: =$E$46*I48 -> 0
J49: =$E$46*I49 -> 0
J50: =$E$46*I50 -> 0
J51: =$E$46*I51 -> 0

Sheet Dashboard
B2: 5-Year Financial Projections - Semis Foods
B4: Amount in INR Lakhs
B5: Revenue | D5: 25-26 | E5: 26-27 | F5: 27-28 | G5: 28-29 | H5: 29-30 | J5: Segmental Revenue | K5: =D5 -> 25-26 | L5: =E5 -> 26-27 | M5: =F5 -> 27-28 | N5: =G5 -> 28-29 | O5: =H5 -> 29-30
B6: ="Revenue from - " &'P&L'!D9 -> Revenue from - Corporate Sales | D6: ='P&L'!F9 -> 135 | E6: ='P&L'!G9 -> 162 | F6: ='P&L'!H9 -> 202.5 | G6: ='P&L'!I9 -> 253.125 | H6: ='P&L'!J9 -> 316.40625 | J6: =B6 -> Revenue from - Corporate Sales | K6: =D6/$D$10 -> 0.21428571 | L6: =E6/$E$10 -> 0.075208914 | M6: =F6/$F$10 -> 0.053066038 | N6: =G6/$G$10 -> 0.042598684 | O6: =H6/$H$10 -> 0.036439809
B7: ="Revenue from - " &'P&L'!D11 -> Revenue from - Millet Cafeteria | D7: ='P&L'!F11 -> 270 | E7: ='P&L'!G11 -> 792 | F7: ='P&L'!H11 -> 1633.5 | G7: ='P&L'!I11 -> 2874.96 | H7: ='P&L'!J11 -> 4348.377 | J7: =B7 -> Revenue from - Millet Cafeteria | K7: =D7/$D$10 -> 0.42857143 | L7: =E7/$E$10 -> 0.36768802 | M7: =F7/$F$10 -> 0.42806604 | N7: =G7/$G$10 -> 0.48383017 | O7: =H7/$H$10 -> 0.50079297
B8: ="Revenue from - " &'P&L'!D13 -> Revenue from - Retail Market Sales | D8: ='P&L'!F13 -> 75 | E8: ='P&L'!G13 -> 600 | F8: ='P&L'!H13 -> 1200 | G8: ='P&L'!I13 -> 1800 | H8: ='P&L'!J13 -> 2700 | J8: =B8 -> Revenue from - Retail Market Sales | K8: =D8/$D$10 -> 0.11904762 | L8: =E8/$E$10 -> 0.27855153 | M8: =F8/$F$10 -> 0.31446541 | N8: =G8/$G$10 -> 0.30292397 | O8: =H8/$H$10 -> 0.31095304
B9: ="Revenue from - " &'P&L'!D15 -> Revenue from - Export Sales | D9: ='P&L'!F15 -> 150 | E9: ='P&L'!G15 -> 600 | F9: ='P&L'!H15 -> 780 | G9: ='P&L'!I15 -> 1014 | H9: ='P&L'!J15 -> 1318.2 | J9: =B9 -> Revenue from - Export Sales | K9: =D9/$D$10 -> 0.23809524 | L9: =E9/$E$10 -> 0.27855153 | M9: =F9/$F$10 -> 0.20440252 | N9: =G9/$G$10 -> 0.17064717 | O9: =H9/$H$10 -> 0.15181418
B10: Total Revenue | D10: =D6+D7+D8+D9 -> 630 | E10: =E6+E7+E8+E9 -> 2154 | F10: =F6+F7+F8+F9 -> 3816 | G10: =G6+G7+G8+G9 -> 5942.085 | H10: =H6+H7+H8+H9 -> 8682.9833 | J10: =B10 -> Total Revenue | K10: =SUM(K6:K9) -> 1 | L10: =SUM(L6:L9) -> 1 | M10: =SUM(M6:M9) -> 1 | N10: =SUM(N6:N9) -> 1 | O10: =SUM(O6:O9) -> 1
B11: % Net Profit | D11: =K22 -> -0.051137554 | E11: =L22 -> 0.14242167 | F11: =M22 -> 0.1488808 | G11: =N22 -> 0.14098645 | H11: =O22 -> 0.21307386
B13: Profit & Loss | D13: =D5 -> 25-26 | E13: =E5 -> 26-27 | F13: =F5 -> 27-28 | G13: =G5 -> 28-29 | H13: =H5 -> 29-30 | J13: Profit & Loss | K13: =D13 -> 25-26 | L13: =E13 -> 26-27 | M13: =F13 -> 27-28 | N13: =G13 -> 28-29 | O13: =H13 -> 29-30
B14: Net Revenue | D14: ='P&L'!F7 -> 630 | E14: ='P&L'!G7 -> 2154 | F14: ='P&L'!H7 -> 3816 | G14: ='P&L'!I7 -> 5942.085 | H14: ='P&L'!J7 -> 8682.9833 | J14: =B14 -> Net Revenue | K14: =D14/D$14 -> 1 | L14: =E14/E$14 -> 1 | M14: =F14/F$14 -> 1 | N14: =G14/G$14 -> 1 | O14: =H14/H$14 -> 1
B15: Direct Cost | D15: ='P&L'!F17 -> 272.4 | E15: ='P&L'!G17 -> 1088.94 | F15: ='P&L'!H17 -> 1818.645 | G15: ='P&L'!I17 -> 2682.005 | H15: ='P&L'!J17 -> 3850.5811 | J15: =B15 -> Direct Cost | K15: =D15/D$14 -> 0.43238095 | L15: =E15/E$14 -> 0.50554318 | M15: =F15/F$14 -> 0.47658412 | N15: =G15/G$14 -> 0.45135755 | O15: =H15/H$14 -> 0.44346292
B16: Gross Profit | D16: =D14-D15 -> 357.6 | E16: =E14-E15 -> 1065.06 | F16: =F14-F15 -> 1997.355 | G16: =G14-G15 -> 3260.0801 | H16: =H14-H15 -> 4832.4021 | J16: =B16 -> Gross Profit | K16: =D16/D$14 -> 0.56761905 | L16: =E16/E$14 -> 0.49445682 | M16: =F16/F$14 -> 0.52341588 | N16: =G16/G$14 -> 0.54864245 | O16: =H16/H$14 -> 0.55653708
B17: Marketing | D17: ='P&L'!F32 -> 20.25 | E17: ='P&L'!G32 -> 47.7 | F17: ='P&L'!H32 -> 91.8 | G17: ='P&L'!I32 -> 156.40425 | H17: ='P&L'!J32 -> 233.23916 | J17: =B17 -> Marketing | K17: =D17/D$14 -> 0.032142857 | L17: =E17/E$14 -> 0.022144847 | M17: =F17/F$14 -> 0.024056604 | N17: =G17/G$14 -> 0.026321443 | O17: =H17/H$14 -> 0.026861639
B18: Payroll | D18: ='P&L'!F36 -> 13.5 | E18: ='P&L'!G36 -> 16.2 | F18: ='P&L'!H36 -> 20.25 | G18: ='P&L'!I36 -> 25.3125 | H18: ='P&L'!J36 -> 31.640625 | J18: =B18 -> Payroll | K18: =D18/D$14 -> 0.021428571 | L18: =E18/E$14 -> 0.0075208914 | M18: =F18/F$14 -> 0.0053066038 | N18: =G18/G$14 -> 0.0042598684 | O18: =H18/H$14 -> 0.0036439809
B19: Other Operating Expenses | D19: ='P&L'!F28-'P&L'!F32-'P&L'!F36 -> 139.05 | E19: ='P&L'!G28-'P&L'!G32-'P&L'!G36 -> 349.38 | F19: ='P&L'!H28-'P&L'!H32-'P&L'!H36 -> 687.69 | G19: ='P&L'!I28-'P&L'!I32-'P&L'!I36 -> 1184.5157 | H19: ='P&L'!J28-'P&L'!J32-'P&L'!J36 -> 1774.9686 | J19: =B19 -> Other Operating Expenses | K19: =D19/D$14 -> 0.22071429 | L19: =E19/E$14 -> 0.16220056 | M19: =F19/F$14 -> 0.18021226 | N19: =G19/G$14 -> 0.19934344 | O19: =H19/H$14 -> 0.20441921
B20: EBITDA | D20: =D16-SUM(D17:D19) -> 184.8 | E20: =E16-SUM(E17:E19) -> 651.78 | F20: =F16-SUM(F17:F19) -> 1197.615 | G20: =G16-SUM(G17:G19) -> 1893.8477 | H20: =H16-SUM(H17:H19) -> 2792.5537 | J20: =B20 -> EBITDA | K20: =D20/D$14 -> 0.29333333 | L20: =E20/E$14 -> 0.30259053 | M20: =F20/F$14 -> 0.31384041 | N20: =G20/G$14 -> 0.3187177 | O20: =H20/H$14 -> 0.32161225
B21: EBIT | D21: ='P&L'!F46 -> 147.44829 | E21: ='P&L'!G46 -> 611.92709 | F21: ='P&L'!H46 -> 1152.6457 | G21: ='P&L'!I46 -> 1840.1825 | H21: ='P&L'!J46 -> 2730.4053 | J21: =B21 -> EBIT | K21: =D21/D$14 -> 0.23404491 | L21: =E21/E$14 -> 0.28408871 | M21: =F21/F$14 -> 0.30205601 | N21: =G21/G$14 -> 0.30968632 | O21: =H21/H$14 -> 0.31445474
B22: Net Profit | D22: ='P&L'!F56 -> -32.216659 | E22: ='P&L'!G56 -> 306.77627 | F22: ='P&L'!H56 -> 568.12913 | G22: ='P&L'!I56 -> 837.75348 | H22: ='P&L'!J56 -> 1850.1168 | J22: =B22 -> Net Profit | K22: =D22/D$14 -> -0.051137554 | L22: =E22/E$14 -> 0.14242167 | M22: =F22/F$14 -> 0.1488808 | N22: =G22/G$14 -> 0.14098645 | O22: =H22/H$14 -> 0.21307386
B24: Cash Flow Statement | D24: =D13 -> 25-26 | E24: =E13 -> 26-27 | F24: =F13 -> 27-28 | G24: =G13 -> 28-29 | H24: =H13 -> 29-30 | J24: Balance Sheet | K24: =K5 -> 25-26 | L24: =L5 -> 26-27 | M24: =M5 -> 27-28 | N24: =N5 -> 28-29 | O24: =O5 -> 29-30
B25: Opening Balance | D25: =CFS!F56 -> 0.3696979 | E25: =CFS!G56 -> 2738.0139 | F25: =CFS!H56 -> 2701.5729 | G25: =CFS!I56 -> 3054.1694 | H25: =CFS!J56 -> 3732.0171 | J25: Assets
B26: Cash Flow from Operating Activities | D26: =CFS!F24 -> 116.49248 | E26: =CFS!G24 -> 448.22137 | F26: =CFS!H24 -> 859.565 | G26: =CFS!I24 -> 1218.814 | H26: =CFS!J24 -> 1612.4049 | J26: Fixed Assets (Tangible & Intangible) | K26: =BS!F38 -> 165.90675 | L26: =BS!G38 -> 190.05384 | M26: =BS!H38 -> 220.08457 | N26: =BS!I38 -> 263.41938 | O26: =BS!J38 -> 304.27091
B27: Cash Flow from Investing Activities | D27: =CFS!F50 -> -43 | E27: =CFS!G50 -> -64 | F27: =CFS!H50 -> -75 | G27: =CFS!I50 -> -97 | H27: =CFS!J50 -> -103 | J27: Current Assets | K27: =BS!F45 -> 2890.2639 | L27: =BS!G45 -> 3079.7525 | M27: =BS!H45 -> 3658.9153 | N27: =BS!I45 -> 4617.9514 | O27: =BS!J45 -> 6040.0091
B28: Cash Flow from Financing Activities | D28: =CFS!F38 -> 2664.1517 | E28: =CFS!G38 -> -420.66236 | F28: =CFS!H38 -> -431.9685 | G28: =CFS!I38 -> -443.96626 | H28: =CFS!J38 -> -456.69755 | J28: Total Assets | K28: =K26+K27 -> 3056.1706 | L28: =L26+L27 -> 3269.8063 | M28: =M26+M27 -> 3878.9999 | N28: =N26+N27 -> 4881.3708 | O28: =O26+O27 -> 6344.28
B29: Net Cash Flow | D29: =D26+D27+D28 -> 2737.6442 | E29: =E26+E27+E28 -> -36.440992 | F29: =F26+F27+F28 -> 352.5965 | G29: =G26+G27+G28 -> 677.84776 | H29: =H26+H27+H28 -> 1052.7073 | J29: Liabilities
B30: Closing Balance | D30: =D25+D29 -> 2738.0139 | E30: =E25+E29 -> 2701.5729 | F30: =F25+F29 -> 3054.1694 | G30: =G25+G29 -> 3732.0171 | H30: =H25+H29 -> 4784.7245 | J30: Current Liabilities | K30: =BS!F21 -> 584.40745 | L30: =BS!G21 -> 756.21774 | M30: =BS!H21 -> 1081.6338 | N30: =BS!I21 -> 1551.5689 | O30: =BS!J21 -> 1490.3971
J31: Non-current liabilities | K31: =BS!F19 -> 2433.8957 | L31: =BS!G19 -> 2168.9448 | M31: =BS!H19 -> 1884.5932 | N31: =BS!I19 -> 1579.2756 | O31: =BS!J19 -> 1253.2398
B32: Valuation Method | D32: Amt in INR Lakhs (Pre Funding) | J32: Equity Share Capital | K32: =BS!F11 -> 37.867463 | L32: =BS!G11 -> 344.64373 | M32: =BS!H11 -> 912.77286 | N32: =BS!I11 -> 1750.5263 | O32: =BS!J11 -> 3600.6431
B33: DCF Perpetual Method | D33: ='Valuation-DCF-Terminal Growth '!C35 -> 1772.8052 | J33: Total Liabilities | K33: =K30+K31+K32 -> 3056.1706 | L33: =L30+L31+L32 -> 3269.8063 | M33: =M30+M31+M32 -> 3878.9999 | N33: =N30+N31+N32 -> 4881.3708 | O33: =O30+O31+O32 -> 6344.28
B34: Comparables - Revenue Multiple Method | D34: ='Valuation-Comparables'!D14 -> 2926.0895
B35: VC Method | E35: ='Valuation-VC '!C13 -> 3473.1933
B36: Average Enterprise Valuation | D36: =AVERAGE(D33:E35) -> 2724.0294
B38: plus Cash in Hand | E38: =Config!C8 -> 0.3696979
B39: minus Existing Debt | E39: =Config!G9 -> 137.06614
B40: Equity Valuation (Post Money) | E40: =D36+E38-E39 -> 2587.3329
B42: Fund Raised (total) | E42: =SUM(Config!C15:C19) -> 300
B43: Equity Valuation (Pre-Money) | E43: =E40-E42 -> 2287.3329
B44: Fund Raised (1st Round) | E44: =Config!C15 -> 300
B45: Equity Dilution | E45: =E44/(E44+E43) -> 0.11594952

Sheet Config
B2: Config
B4: Feel free to change the cells in orange
B7: Opening Balance - Current Assets in Lakhs | C7: Value | F7: Liabilities in Lakhs | G7: Value
B8: Cash in Hand | C8: =36969.79/100000 -> 0.3696979 | F8: Opening A/C Payable | G8: =8279574.94/100000 -> 82.795749
B9: Opening Inventory | C9: =3175974.94/100000 -> 31.759749 | F9: Opening Loan | G9: =13706613.83/100000 -> 137.06614
B10: Opening A/C Receivable | C10: =6062984.61/100000 -> 60.629846
B14: Funding Round | C14: Amount | D14: Month
B15: Round-1 | C15: 300 | D15: M1
B16: Round-2 | C16: 0 | D16: M13
B17: Round-3 | D17: M25
B18: Round-4 | D18: M37
B19: Round-5
B21: Round | C21: M1 | D21: M2 | E21: M3 | F21: M4 | G21: M5 | H21: M6 | I21: M7 | J21: M8 | K21: M9 | L21: M10 | M21: M11 | N21: M12 | O21: M13 | P21: M14 | Q21: M15 | R21: M16 | S21: M17 | T21: M18 | U21: M19 | V21: M20 | W21: M21 | X21: M22 | Y21: M23 | Z21: M24 | AA21: M25 | AB21: M26 | AC21: M27 | AD21: M28 | AE21: M29 | AF21: M30 | AG21: M31 | AH21: M32 | AI21: M33 | AJ21: M34 | AK21: M35 | AL21: M36 | AM21: M37 | AN21: M38 | AO21: M39 | AP21: M40 | AQ21: M41 | AR21: M42 | AS21: M43 | AT21: M44 | AU21: M45 | AV21: M46 | AW21: M47 | AX21: M48 | AY21: M49 | AZ21: M50 | BA21: M51 | BB21: M52 | BC21: M53 | BD21: M54 | BE21: M55 | BF21: M56 | BG21: M57 | BH21: M58 | BI21: M59 | BJ21: M60
B22: =B15 -> Round-1 | C22: =IF(C$21=$D$15,$C$15,0) -> 300 | D22: =IF(D$21=$D$15,$C$15,0) -> 0 | E22: =IF(E$21=$D$15,$C$15,0) -> 0 | F22: =IF(F$21=$D$15,$C$15,0) -> 0 | G22: =IF(G$21=$D$15,$C$15,0) -> 0 | H22: =IF(H$21=$D$15,$C$15,0) -> 0 | I22: =IF(I$21=$D$15,$C$15,0) -> 0 | J22: =IF(J$21=$D$15,$C$15,0) -> 0 | ... BJ22: =IF(BJ$21=$D$15,$C$15,0) -> 0
B23: =B16 -> Round-2 | C23: =IF(C$21=$D$16,$C$16,0) -> 0 | D23: =IF(D$21=$D$16,$C$16,0) -> 0 | E23: =IF(E$21=$D$16,$C$16,0) -> 0 | F23: =IF(F$21=$D$16,$C$16,0) -> 0 | G23: =IF(G$21=$D$16,$C$16,0) -> 0 | H23: =IF(H$21=$D$16,$C$16,0) -> 0 | I23: =IF(I$21=$D$16,$C$16,0) -> 0 | J23: =IF(J$21=$D$16,$C$16,0) -> 0 | ... BJ23: =IF(BJ$21=$D$16,$C$16,0) -> 0
B24: =B17 -> Round-3 | C24: =IF(C$21=$D$17,$C$17,0) -> 0 | D24: =IF(D$21=$D$17,$C$17,0) -> 0 | E24: =IF(E$21=$D$17,$C$17,0) -> 0 | F24: =IF(F$21=$D$17,$C$17,0) -> 0 | G24: =IF(G$21=$D$17,$C$17,0) -> 0 | H24: =IF(H$21=$D$17,$C$17,0) -> 0 | I24: =IF(I$21=$D$17,$C$17,0) -> 0 | J24: =IF(J$21=$D$17,$C$17,0) -> 0 | ... BJ24: =IF(BJ$21=$D$17,$C$17,0) -> 0
B25: =B18 -> Round-4 | C25: =IF(C$21=$D$18,$C$18,0) -> 0 | D25: =IF(D$21=$D$18,$C$18,0) -> 0 | E25: =IF(E$21=$D$18,$C$18,0) -> 0 | F25: =IF(F$21=$D$18,$C$18,0) -> 0 | G25: =IF(G$21=$D$18,$C$18,0) -> 0 | H25: =IF(H$21=$D$18,$C$18,0) -> 0 | I25: =IF(I$21=$D$18,$C$18,0) -> 0 | J25: =IF(J$21=$D$18,$C$18,0) -> 0 | ... BJ25: =IF(BJ$21=$D$18,$C$18,0) -> 0
B26: =B19 -> Round-5 | C26: =IF(C$21=$D$19,$C$19,0) -> 0 | D26: =IF(D$21=$D$19,$C$19,0) -> 0 | E26: =IF(E$21=$D$19,$C$19,0) -> 0 | F26: =IF(F$21=$D$19,$C$19,0) -> 0 | G26: =IF(G$21=$D$19,$C$19,0) -> 0 | H26: =IF(H$21=$D$19,$C$19,0) -> 0 | I26: =IF(I$21=$D$19,$C$19,0) -> 0 | J26: =IF(J$21=$D$19,$C$19,0) -> 0 | ... BJ26: =IF(BJ$21=$D$19,$C$19,0) -> 0
B27: Total | C27: =SUM(C22:C26) -> 300 | D27: =SUM(D22:D26) -> 0 | E27: =SUM(E22:E26) -> 0 | F27: =SUM(F22:F26) -> 0 | G27: =SUM(G22:G26) -> 0 | H27: =SUM(H22:H26) -> 0 | I27: =SUM(I22:I26) -> 0 | J27: =SUM(J22:J26) -> 0 | ... BJ27: =SUM(BJ22:BJ26) -> 0
B29: Effective Income Tax | C29: 25-26 | D29: 26-27 | E29: 27-28 | F29: 28-29 | G29: 29-30
B30: Total Funding in Lakhs | C30: =SUM(C27:N27) -> 300 | D30: =SUM(O27:Z27) -> 0 | E30: =SUM(AA27:AL27) -> 0 | F30: =SUM(AM27:AX27) -> 0 | G30: =SUM(AY27:BJ27) -> 0

Sheet PAG-2
B5: Annual Sales / Revenue
B7: SI No. | D7: Particulars | F7: FY 2025-26 (₹)
B9: 1 | D9: Corporate Sales | F9: =WC!E7*Ro -> 13500000
B11: =B9+1 -> 2 | D11: Millet Cafeteria | F11: =WC!E8*Ro -> 27000000
B13: =B11+1 -> 3 | D13: Retail Market Sales | F13: =WC!E9*Ro -> 7500000
B15: =B13+1 -> 4 | D15: Export Sales | F15: =WC!E10*Ro -> 15000000
B17: Total | F17: =SUM(F9:F15) -> 63000000

Sheet BS
B2: Check (Assets - Liabilities) | F2: =F56-F32 -> 0 | G2: =G56-G32 -> 0 | H2: =H56-H32 -> 0 | I2: =I56-I32 -> 0 | J2: =J56-J32 -> 0 | K2: =K56-K32 -> 0 | L2: =L56-L32 -> 0 | M2: =M56-M32 -> 0 | ... O2: =O56-O32 -> 0
B4: Balance sheet
O5: =Do -> (₹ in Lakhs)
B7: SI No. | D7: Particulars | F7: 25-26 | G7: 26-27 | H7: 27-28 | I7: 28-29 | J7: 29-30 | K7: 30-31 | L7: 31-32 | M7: 32-33 | N7: 33-34 | O7: 34-35
B9: Liabilities
B11: A | D11: Closing Capital ( i + ii + iii - iv ) | F11: =F13+F15+F17 -> 37.867463 | G11: =G13+G15+G17 -> 344.64373 | H11: =H13+H15+H17 -> 912.77286 | I11: =I13+I15+I17 -> 1750.5263 | J11: =J13+J15+J17 -> 3600.6431 | K11: =K13+K15+K17 -> 5995.5619 | L11: =L13+L15+L17 -> 9069.7514 | M11: =M13+M15+M17 -> 12972.938 | ... O11: =O13+O15+O17 -> 23852.186
D13: i) Equity Capital | F13: 75 | G13: =F13 -> 75 | H13: =G13 -> 75 | I13: =H13 -> 75 | J13: =I13 -> 75 | K13: =J13 -> 75 | L13: =K13 -> 75 | M13: =L13 -> 75 | N13: =M13 -> 75 | O13: =N13 -> 75
D15: ii) Additional Capital | F15: =CFS!F30 -> 300 | G15: =F15+CFS!G30 -> 300 | H15: =G15+CFS!H30 -> 300 | I15: =H15+CFS!I30 -> 300 | J15: =I15+CFS!J30 -> 300 | K15: =J15+CFS!K30 -> 300 | L15: =K15+CFS!L30 -> 300 | M15: =L15+CFS!M30 -> 300 | N15: =M15+CFS!N30 -> 300 | O15: =N15+CFS!O30 -> 300
D17: iii) Profit / (Loss) | F17: ='P&L'!F56+(-30491587.8/10^5) -> -337.13254 | G17: ='P&L'!G56+F17 -> -30.356269 | H17: ='P&L'!H56+G17 -> 537.77286 | I17: ='P&L'!I56+H17 -> 1375.5263 | J17: ='P&L'!J56+I17 -> 3225.6431 | K17: ='P&L'!K56+J17 -> 5620.5619 | L17: ='P&L'!L56+K17 -> 8694.7514 | M17: ='P&L'!M56+L17 -> 12597.938 | N17: ='P&L'!N56+M17 -> 17470.025 | O17: ='P&L'!O56+N17 -> 23477.186
B19: B | D19: Non-Current Liabilities | F19: ='Debt Schedule'!C70 -> 2433.8957 | G19: ='Debt Schedule'!D70 -> 2168.9448 | H19: ='Debt Schedule'!E70 -> 1884.5932 | I19: ='Debt Schedule'!F70 -> 1579.2756 | J19: ='Debt Schedule'!G70 -> 1253.2398 | K19: ='Debt Schedule'!H70 -> 968.47482 | L19: ='Debt Schedule'!I70 -> 665.48845 | M19: ='Debt Schedule'!J70 -> 343.08801 | ... O19: ='Debt Schedule'!L70 -> 1.5254464e-13
B21: C | D21: Current Liabilities | F21: =SUM(F22:F29) -> 584.40745 | G21: =SUM(G22:G29) -> 756.21774 | H21: =SUM(H22:H29) -> 1081.6338 | I21: =SUM(I22:I29) -> 1551.5689 | J21: =SUM(J22:J29) -> 1490.3971 | K21: =SUM(K22:K29) -> 1776.6574 | L21: =SUM(L22:L29) -> 2122.5867 | M21: =SUM(M22:M29) -> 2542.9617 | ... O21: =SUM(O22:O29) -> 3247.1477
D23: Trade Payables | F23: =WC!E38 -> 7.4630137 | G23: =WC!F38 -> 29.833973 | H23: =WC!G38 -> 49.82589 | I23: =WC!H38 -> 73.479588 | J23: =WC!I38 -> 105.49537 | K23: =WC!J38 -> 135.54124 | L23: =WC!K38 -> 172.13322 | M23: =WC!L38 -> 217.80956 | ... O23: =WC!N38 -> 342.6926 | X23: Payables Days | Z23: 0
D25: Other liabilities | F25: =(31476895.65+1518839.4)/100000 -> 329.95735 | G25: =F25 -> 329.95735 | H25: =G25 -> 329.95735 | I25: =H25 -> 329.95735 | J25: =I25 -> 329.95735 | K25: =J25 -> 329.95735 | L25: =K25 -> 329.95735 | M25: =L25 -> 329.95735 | N25: =M25 -> 329.95735 | O25: =N25 -> 329.95735
D27: Current portion of Loang term Debt | F27: ='Debt Schedule'!C69 -> 246.98709 | G27: ='Debt Schedule'!D69 -> 264.95088 | H27: ='Debt Schedule'!E69 -> 284.3516 | I27: ='Debt Schedule'!F69 -> 305.31765 | J27: ='Debt Schedule'!G69 -> 326.03574 | K27: ='Debt Schedule'!H69 -> 284.76501 | L27: ='Debt Schedule'!I69 -> 302.98637 | M27: ='Debt Schedule'!J69 -> 322.40044 | ... O27: ='Debt Schedule'!L69 -> 0
D29: Provision for Tax | F29: ='P&L'!F54 -> 0 | G29: ='P&L'!G54 -> 131.47554 | H29: ='P&L'!H54 -> 417.49898 | I29: ='P&L'!I54 -> 842.81432 | J29: ='P&L'!J54 -> 728.90861 | K29: ='P&L'!K54 -> 1026.3937 | L29: ='P&L'!L54 -> 1317.5098 | M29: ='P&L'!M54 -> 1672.7943 | ... O29: ='P&L'!O54 -> 2574.4977
D32: Total Liabilities | F32: =F11+F19+F21 -> 3056.1706 | G32: =G11+G19+G21 -> 3269.8063 | H32: =H11+H19+H21 -> 3878.9999 | I32: =I11+I19+I21 -> 4881.3708 | J32: =J11+J19+J21 -> 6344.28 | K32: =K11+K19+K21 -> 8740.694 | L32: =L11+L19+L21 -> 11857.827 | M32: =M11+M19+M21 -> 15858.988 | ... O32: =O11+O19+O21 -> 27099.334
B36: Assets
B38: D | D38: Non-Current Assets | F38: =SUM(F40:F42) -> 165.90675 | G38: =SUM(G40:G42) -> 190.05384 | H38: =SUM(H40:H42) -> 220.08457 | I38: =SUM(I40:I42) -> 263.41938 | J38: =SUM(J40:J42) -> 304.27091 | K38: =SUM(K40:K42) -> 338.0183 | L38: =SUM(L40:L42) -> 396.15422 | M38: =SUM(M40:M42) -> 443.90101 | ... O38: =SUM(O40:O42) -> 597.55329
D40: Fixed Assets | F40: =DAS!F90 -> 142.86852 | G40: =DAS!H90 -> 167.01561 | H40: =DAS!J90 -> 197.04634 | I40: =DAS!L90 -> 240.38115 | J40: =DAS!N90 -> 281.23268 | K40: =DAS!P90 -> 314.98007 | L40: =DAS!R90 -> 373.11599 | M40: =DAS!T90 -> 420.86278 | N40: =DAS!V90 -> 480.53499 | O40: =DAS!X90 -> 574.51506
D42: Other Non-Current Assets | F42: =(145000+333223+1825600)/100000 -> 23.03823 | G42: =F42 -> 23.03823 | H42: =G42 -> 23.03823 | I42: =H42 -> 23.03823 | J42: =I42 -> 23.03823 | K42: =J42 -> 23.03823 | L42: =K42 -> 23.03823 | M42: =L42 -> 23.03823 | N42: =M42 -> 23.03823 | O42: =N42 -> 23.03823
B45: E | D45: Current Assets | F45: =SUM(F46:F53) -> 2890.2639 | G45: =SUM(G46:G53) -> 3079.7525 | H45: =SUM(H46:H53) -> 3658.9153 | I45: =SUM(I46:I53) -> 4617.9514 | J45: =SUM(J46:J53) -> 6040.0091 | K45: =SUM(K46:K53) -> 8402.6757 | L45: =SUM(L46:L53) -> 11461.672 | M45: =SUM(M46:M53) -> 15415.087 | ... O45: =SUM(O46:O53) -> 26501.78
D47: Inventory | F47: =WC!E52 -> 33.583562 | G47: =WC!F52 -> 134.25288 | H47: =WC!G52 -> 224.21651 | I47: =WC!H52 -> 330.65814 | J47: =WC!I52 -> 474.72918 | K47: =WC!J52 -> 609.93559 | L47: =WC!K52 -> 774.59949 | M47: =WC!L52 -> 980.14301 | ... O47: =WC!N52 -> 1542.1167
D49: Trade Receivables | F49: =WC!E24 -> 51.780822 | G49: =WC!F24 -> 177.0411 | H49: =WC!G24 -> 313.64384 | I49: =WC!H24 -> 488.39055 | J49: =WC!I24 -> 713.66986 | K49: =WC!J24 -> 928.37102 | L49: =WC!K24 -> 1179.4466 | M49: =WC!L24 -> 1487.0456 | ... O49: =WC!N24 -> 2278.508 | X49: Receivables Days | Z49: 0
D51: Cash and Cash equivalence | F51: =CFS!F58 -> 2738.0139 | G51: =CFS!G58 -> 2701.5729 | H51: =CFS!H58 -> 3054.1694 | I51: =CFS!I58 -> 3732.0171 | J51: =CFS!J58 -> 4784.7245 | K51: =CFS!K58 -> 6797.4835 | L51: =CFS!L58 -> 9440.7406 | M51: =CFS!M58 -> 12881.013 | ... O51: =CFS!O58 -> 22614.27
D53: Other Current Assets | F53: =(6617160.89+71400)/100000 -> 66.885609 | G53: =F53 -> 66.885609 | H53: =G53 -> 66.885609 | I53: =H53 -> 66.885609 | J53: =I53 -> 66.885609 | K53: =J53 -> 66.885609 | L53: =K53 -> 66.885609 | M53: =L53 -> 66.885609 | N53: =M53 -> 66.885609 | O53: =N53 -> 66.885609 | X53: Advance Tax
D56: Total Assets | F56: =F38+F45 -> 3056.1706 | G56: =G38+G45 -> 3269.8063 | H56: =H38+H45 -> 3878.9999 | I56: =I38+I45 -> 4881.3708 | J56: =J38+J45 -> 6344.28 | K56: =K38+K45 -> 8740.694 | L56: =L38+L45 -> 11857.827 | M56: =M38+M45 -> 15858.988 | ... O56: =O38+O45 -> 27099.334
F57: =F56-F32 -> 0 | G57: =G56-G32 -> 0 | H57: =H56-H32 -> 0 | I57: =I56-I32 -> 0 | J57: =J56-J32 -> 0 | K57: =K56-K32 -> 0 | L57: =L56-L32 -> 0 | M57: =M56-M32 -> 0 | ... O57: =O56-O32 -> 0
B62: Net Worth | F62: =F11 -> 37.867463 | G62: =G11 -> 344.64373 | H62: =H11 -> 912.77286 | I62: =I11 -> 1750.5263 | J62: =J11 -> 3600.6431 | K62: =K11 -> 5995.5619 | L62: =L11 -> 9069.7514 | M62: =M11 -> 12972.938 | ... O62: =O11 -> 23852.186
B64: Average Net Worth | F64: =(E62+F62)/2 -> 18.933732 | G64: =(F62+G62)/2 -> 191.2556 | H64: =(G62+H62)/2 -> 628.7083 | I64: =(H62+I62)/2 -> 1331.6496 | J64: =(I62+J62)/2 -> 2675.5847 | K64: =(J62+K62)/2 -> 4798.1025 | L64: =(K62+L62)/2 -> 7532.6566 | M64: =(L62+M62)/2 -> 11021.345 | ... O64: =(N62+O62)/2 -> 20848.605
B66: Capital Employed | F66: =F11+F19 -> 2471.7632 | G66: =G11+G19 -> 2513.5886 | H66: =H11+H19 -> 2797.3661 | I66: =I11+I19 -> 3329.8019 | J66: =J11+J19 -> 4853.8829 | K66: =K11+K19 -> 6964.0367 | L66: =L11+L19 -> 9735.2398 | M66: =M11+M19 -> 13316.026 | ... O66: =O11+O19 -> 23852.186
B68: Average Capital Employed | F68: =(E66+F66)/2 -> 1235.8816 | G68: =(F66+G66)/2 -> 2492.6759 | H68: =(G66+H66)/2 -> 2655.4773 | I68: =(H66+I66)/2 -> 3063.584 | J68: =(I66+J66)/2 -> 4091.8424 | K68: =(J66+K66)/2 -> 5908.9598 | L68: =(K66+L66)/2 -> 8349.6383 | M68: =(L66+M66)/2 -> 11525.633 | ... O68: =(N66+O66)/2 -> 20848.605
B70: Fixed Assets | F70: =F40 -> 142.86852 | G70: =G40 -> 167.01561 | H70: =H40 -> 197.04634 | I70: =I40 -> 240.38115 | J70: =J40 -> 281.23268 | K70: =K40 -> 314.98007 | L70: =L40 -> 373.11599 | M70: =M40 -> 420.86278 | ... O70: =O40 -> 574.51506
B72: Average Fixed Assets | F72: =(E70+F70)/2 -> 71.43426 | G72: =(F70+G70)/2 -> 154.94206 | H72: =(G70+H70)/2 -> 182.03098 | I72: =(H70+I70)/2 -> 218.71375 | J72: =(I70+J70)/2 -> 260.80691 | K72: =(J70+K70)/2 -> 298.10637 | L72: =(K70+L70)/2 -> 344.04803 | M72: =(L70+M70)/2 -> 396.98939 | ... O72: =(N70+O70)/2 -> 527.52503
B74: Total Assets | F74: =F56 -> 3056.1706 | G74: =G56 -> 3269.8063 | H74: =H56 -> 3878.9999 | I74: =I56 -> 4881.3708 | J74: =J56 -> 6344.28 | K74: =K56 -> 8740.694 | L74: =L56 -> 11857.827 | M74: =M56 -> 15858.988 | ... O74: =O56 -> 27099.334
B76: Average Fixed Assets | F76: =(E74+F74)/2 -> 1528.0853 | G76: =(F74+G74)/2 -> 3162.9885 | H76: =(G74+H74)/2 -> 3574.4031 | I76: =(H74+I74)/2 -> 4380.1854 | J76: =(I74+J74)/2 -> 5612.8254 | K76: =(J74+K74)/2 -> 7542.487 | L76: =(K74+L74)/2 -> 10299.26 | M76: =(L74+M74)/2 -> 13858.407 | ... O76: =(N74+O74)/2 -> 23989.617
B79: Increase in Trade Receivables | F79: =Config!C10-BS!F49 -> 8.8490242 | G79: =F49-G49 -> -125.26027 | H79: =G49-H49 -> -136.60274 | I79: =H49-I49 -> -174.74671 | J79: =I49-J49 -> -225.27931 | K79: =J49-K49 -> -214.70116 | L79: =K49-L49 -> -251.07563 | M79: =L49-M49 -> -307.59896 | N79: =M49-N49 -> -362.34944 | O79: =N49-O49 -> -429.11297
B81: Increase in Trade Pyables | F81: =F23-Config!G8 -> -75.332736 | G81: =G23-F23 -> 22.370959 | H81: =H23-G23 -> 19.991918 | I81: =I23-H23 -> 23.653697 | J81: =J23-I23 -> 32.015786 | K81: =K23-J23 -> 30.04587 | L81: =L23-K23 -> 36.591977 | M81: =M23-L23 -> 45.676339 | N81: =N23-M23 -> 55.983834 | O81: =O23-N23 -> 68.899208
B83: Increase in Inventory | F83: =Config!C9-BS!F47 -> -1.8238122 | G83: =F47-G47 -> -100.66932 | H83: =G47-H47 -> -89.96363 | I83: =H47-I47 -> -106.44164 | J83: =I47-J47 -> -144.07104 | K83: =J47-K47 -> -135.20641 | L83: =K47-L47 -> -164.6639 | M83: =L47-M47 -> -205.54352 | N83: =M47-N47 -> -251.92725 | O83: =N47-O47 -> -310.04643

Sheet P&L
B2: Profitability Statement
O3: =Do -> (₹ in Lakhs)
B5: SI No. | D5: Particulars | F5: =[2]Ratios!F4 -> 2025-26 | G5: =[2]Ratios!H4 -> 2026-27 | H5: =[2]Ratios!J4 -> 2027-28 | I5: =[2]Ratios!L4 -> 2028-29 | J5: =[2]Ratios!N4 -> 2029-30 | K5: =[2]Ratios!P4 -> 2030-31 | L5: =[2]Ratios!R4 -> 2031-32 | M5: =[2]Ratios!T4 -> 2032-33 | N5: =[2]Ratios!V4 -> 2033-34 | O5: =[2]Ratios!X4 -> 2034-35 | Q5: Ref Sheet
B7: 1 | D7: Revenue from Operations | F7: =SUM(F8:F15) -> 630 | G7: =SUM(G8:G15) -> 2154 | H7: =SUM(H8:H15) -> 3816 | I7: =SUM(I8:I15) -> 5942.085 | J7: =SUM(J8:J15) -> 8682.9833 | K7: =SUM(K8:K15) -> 11295.181 | L7: =SUM(L8:L15) -> 14349.934 | M7: =SUM(M8:M15) -> 18092.388 | ... O7: =SUM(O8:O15) -> 27721.848 | Q7: RFO
D9: ='PAG-2'!D9 -> Corporate Sales | F9: {=TRANSPOSE('Revenue generation breakup'!D7:D16)} -> 135 | G9: 162 | H9: 202.5 | I9: 253.125 | J9: 316.40625 | K9: 395.50781 | L9: 494.38477 | M9: 617.98096 | N9: 772.4762 | O9: 965.59525
D11: ='PAG-2'!D11 -> Millet Cafeteria | F11: {=TRANSPOSE('Revenue generation breakup'!E7:E16)} -> 270 | G11: 792 | H11: 1633.5 | I11: 2874.96 | J11: 4348.377 | K11: 5811.0129 | L11: 7409.0414 | M11: 9304.8844 | N11: 11371.789 | O11: 13622.122
D13: ='PAG-2'!D13 -> Retail Market Sales | F13: {=TRANSPOSE('Revenue generation breakup'!F7:F16)} -> 75 | G13: 600 | H13: 1200 | I13: 1800 | J13: 2700 | K13: 3375 | L13: 4218.75 | M13: 5273.4375 | N13: 6591.7969 | O13: 8239.7461
D15: ='PAG-2'!D15 -> Export Sales | F15: {=TRANSPOSE('Revenue generation breakup'!G7:G16)} -> 150 | G15: 600 | H15: 780 | I15: 1014 | J15: 1318.2 | K15: 1713.66 | L15: 2227.758 | M15: 2896.0854 | N15: 3764.911 | O15: 4894.3843
B17: 2 | D17: Cost of Materials Sold | F17: =SUM(F19:F23) -> 272.4 | G17: =SUM(G19:G23) -> 1088.94 | H17: =SUM(H19:H23) -> 1818.645 | I17: =SUM(I19:I23) -> 2682.005 | J17: =SUM(J19:J23) -> 3850.5811 | K17: =SUM(K19:K23) -> 4947.2554 | L17: =SUM(L19:L23) -> 6282.8625 | M17: =SUM(M19:M23) -> 7950.0489 | ... O17: =SUM(O19:O23) -> 12508.28 | Q17: MC
D19: ='All Costs'!D19 -> Direct Cost (Corporate Sales ) | F19: ='All Costs'!E19 -> 47.25 | G19: ='All Costs'!F19 -> 56.7 | H19: ='All Costs'!G19 -> 70.875 | I19: ='All Costs'!H19 -> 88.59375 | J19: ='All Costs'!I19 -> 110.74219 | K19: ='All Costs'!J19 -> 138.42773 | L19: ='All Costs'!K19 -> 173.03467 | M19: ='All Costs'!L19 -> 216.29333 | ... O19: ='All Costs'!N19 -> 337.95834
D21: ='All Costs'!D20 -> Direct Cost ( Millet Cafeteria ) | F21: ='All Costs'!E20 -> 59.4 | G21: ='All Costs'!F20 -> 174.24 | H21: ='All Costs'!G20 -> 359.37 | I21: ='All Costs'!H20 -> 632.4912 | J21: ='All Costs'!I20 -> 956.64294 | K21: ='All Costs'!J20 -> 1278.4228 | L21: ='All Costs'!K20 -> 1629.9891 | M21: ='All Costs'!L20 -> 2047.0746 | ... O21: ='All Costs'!N20 -> 2996.8668
D23: Direct Cost (Retail + Exports) | F23: ='All Costs'!E22+'All Costs'!E21 -> 165.75 | G23: ='All Costs'!F22+'All Costs'!F21 -> 858 | H23: ='All Costs'!G22+'All Costs'!G21 -> 1388.4 | I23: ='All Costs'!H22+'All Costs'!H21 -> 1960.92 | J23: ='All Costs'!I22+'All Costs'!I21 -> 2783.196 | K23: ='All Costs'!J22+'All Costs'!J21 -> 3530.4048 | L23: ='All Costs'!K22+'All Costs'!K21 -> 4479.8387 | M23: ='All Costs'!L22+'All Costs'!L21 -> 5686.681 | ... O23: ='All Costs'!N22+'All Costs'!N21 -> 9173.4547
B25: 3 | D25: Gross Profit [1-2] | F25: =F7-F17 -> 357.6 | G25: =G7-G17 -> 1065.06 | H25: =H7-H17 -> 1997.355 | I25: =I7-I17 -> 3260.0801 | J25: =J7-J17 -> 4832.4021 | K25: =K7-K17 -> 6347.9253 | L25: =L7-L17 -> 8067.0717 | M25: =M7-M17 -> 10142.339 | ... O25: =O7-O17 -> 15213.568
D26: Gross Profit % | F26: =F25/F$7 -> 0.56761905 | G26: =G25/G$7 -> 0.49445682 | H26: =H25/H$7 -> 0.52341588 | I26: =I25/I$7 -> 0.54864245 | J26: =J25/J$7 -> 0.55653708 | K26: =K25/K$7 -> 0.56200299 | L26: =L25/L$7 -> 0.56216785 | M26: =M25/M$7 -> 0.56058599 | ... O26: =O25/O$7 -> 0.54879343
B28: 4 | D28: Indirect Expenses | F28: =SUM(F30:F39) -> 172.8 | G28: =SUM(G30:G40) -> 413.28 | H28: =SUM(H30:H40) -> 799.74 | I28: =SUM(I30:I40) -> 1366.2324 | J28: =SUM(J30:J39) -> 2039.8484 | K28: =SUM(K30:K39) -> 2715.0488 | L28: =SUM(L30:L39) -> 3457.7321 | M28: =SUM(M30:M39) -> 4341.3415 | N28: =SUM(N30:N39) -> 5312.5777 | O28: =SUM(O30:O39) -> 6379.9718
D30: Employee Costs | F30: ='All Costs'!E29+'All Costs'!E30 -> 101.25 | G30: ='All Costs'!F29+'All Costs'!F30 -> 238.5 | H30: ='All Costs'!G29+'All Costs'!G30 -> 459 | I30: ='All Costs'!H29+'All Costs'!H30 -> 782.02125 | J30: ='All Costs'!I29+'All Costs'!I30 -> 1166.1958 | K30: ='All Costs'!J29+'All Costs'!J30 -> 1551.6302 | L30: ='All Costs'!K29+'All Costs'!K30 -> 1975.8566 | M30: ='All Costs'!L29+'All Costs'!L30 -> 2480.7163 | ... O30: ='All Costs'!N29+'All Costs'!N30 -> 3646.9293 | Q30: IE
D32: Promotional Expenses | F32: ='All Costs'!E37+'All Costs'!E38 -> 20.25 | G32: ='All Costs'!F37+'All Costs'!F38 -> 47.7 | H32: ='All Costs'!G37+'All Costs'!G38 -> 91.8 | I32: ='All Costs'!H37+'All Costs'!H38 -> 156.40425 | J32: ='All Costs'!I37+'All Costs'!I38 -> 233.23916 | K32: ='All Costs'!J37+'All Costs'!J38 -> 310.32604 | L32: ='All Costs'!K37+'All Costs'!K38 -> 395.17131 | M32: ='All Costs'!L37+'All Costs'!L38 -> 496.14327 | ... O32: ='All Costs'!N37+'All Costs'!N38 -> 729.38586 | Q32: IE
D34: Rent | F34: ='All Costs'!E51 -> 27 | G34: ='All Costs'!F51 -> 79.2 | H34: ='All Costs'!G51 -> 163.35 | I34: ='All Costs'!H51 -> 287.496 | J34: ='All Costs'!I51 -> 434.8377 | K34: ='All Costs'!J51 -> 581.10129 | L34: ='All Costs'!K51 -> 740.90414 | M34: ='All Costs'!L51 -> 930.48844 | ... O34: ='All Costs'!N51 -> 1362.2122 | Q34: IE
D36: Other Expenses | F36: ='All Costs'!E44 -> 13.5 | G36: ='All Costs'!F44 -> 16.2 | H36: ='All Costs'!G44 -> 20.25 | I36: ='All Costs'!H44 -> 25.3125 | J36: ='All Costs'!I44 -> 31.640625 | K36: ='All Costs'!J44 -> 39.550781 | L36: ='All Costs'!K44 -> 49.438477 | M36: ='All Costs'!L44 -> 61.798096 | ... O36: ='All Costs'!N44 -> 96.559525 | Q36: IE
D38: Misc Expenses | F38: ='All Costs'!E52 -> 10.8 | G38: ='All Costs'!F52 -> 31.68 | H38: ='All Costs'!G52 -> 65.34 | I38: ='All Costs'!H52 -> 114.9984 | J38: ='All Costs'!I52 -> 173.93508 | K38: ='All Costs'!J52 -> 232.44052 | L38: ='All Costs'!K52 -> 296.36166 | M38: ='All Costs'!L52 -> 372.19538 | ... O38: ='All Costs'!N52 -> 544.88488 | Q38: IE
B41: 5 | D41: EBITDA [3-4] | F41: =F25-F28 -> 184.8 | G41: =G25-G28 -> 651.78 | H41: =H25-H28 -> 1197.615 | I41: =I25-I28 -> 1893.8477 | J41: =J25-J28 -> 2792.5537 | K41: =K25-K28 -> 3632.8765 | L41: =L25-L28 -> 4609.3395 | M41: =M25-M28 -> 5800.9979 | ... O41: =O25-O28 -> 8833.596
D42: EBITDA % | F42: =F41/F$7 -> 0.29333333 | G42: =G41/G$7 -> 0.30259053 | H42: =H41/H$7 -> 0.31384041 | I42: =I41/I$7 -> 0.3187177 | J42: =J41/J$7 -> 0.32161225 | K42: =K41/K$7 -> 0.32163067 | L42: =L41/L$7 -> 0.3212098 | M42: =M41/M$7 -> 0.32063196 | ... O42: =O41/O$7 -> 0.31865105
B44: 6 | D44: Depreciation & Amortisation | F44: =DAS!F85 -> 37.351708 | G44: =DAS!H85 -> 39.852912 | H44: =DAS!J85 -> 44.969264 | I44: =DAS!L85 -> 53.665192 | J44: =DAS!N85 -> 62.148476 | K44: =DAS!P85 -> 69.252604 | L44: =DAS!R85 -> 81.864079 | M44: =DAS!T85 -> 92.253211 | N44: =DAS!V85 -> 105.32779 | O44: =DAS!X85 -> 126.01992 | Q44: DAS
B46: 7 | D46: EBIT [5-7] | F46: =F41-F44 -> 147.44829 | G46: =G41-G44 -> 611.92709 | H46: =H41-H44 -> 1152.6457 | I46: =I41-I44 -> 1840.1825 | J46: =J41-J44 -> 2730.4053 | K46: =K41-K44 -> 3563.6239 | L46: =L41-L44 -> 4527.4755 | M46: =M41-M44 -> 5708.7446 | ... O46: =O41-O44 -> 8707.576
D47: EBIT % | F47: =F46/F$7 -> 0.23404491 | G47: =G46/G$7 -> 0.28408871 | H47: =H46/H$7 -> 0.30205601 | I47: =I46/I$7 -> 0.30968632 | J47: =J46/J$7 -> 0.31445474 | K47: =K46/K$7 -> 0.31549951 | L47: =L46/L$7 -> 0.31550496 | M47: =M46/M$7 -> 0.31553295 | ... O47: =O46/O$7 -> 0.31410518
B49: 8 | D49: Finance Cost | F49: ='Debt Schedule'!C66 -> 179.66495 | G49: ='Debt Schedule'!D66 -> 173.67528 | H49: ='Debt Schedule'!E66 -> 167.01762 | I49: ='Debt Schedule'!F66 -> 159.61466 | J49: ='Debt Schedule'!G66 -> 151.37989 | K49: ='Debt Schedule'!H66 -> 142.31144 | L49: ='Debt Schedule'!I66 -> 135.77614 | M49: ='Debt Schedule'!J66 -> 132.7635 | ... O49: ='Debt Schedule'!L66 -> 125.917 | Q49: LRS
B51: 9 | D51: PBT [8-9] | F51: =F46-F49 -> -32.216659 | G51: =G46-G49 -> 438.25181 | H51: =H46-H49 -> 985.62811 | I51: =I46-I49 -> 1680.5678 | J51: =J46-J49 -> 2579.0254 | K51: =K46-K49 -> 3421.3125 | L51: =L46-L49 -> 4391.6993 | M51: =M46-M49 -> 5575.9811 | ... O51: =O46-O49 -> 8581.659
D52: PBT % | F52: =F51/F$7 -> -0.051137554 | G52: =G51/G$7 -> 0.20345952 | H52: =H51/H$7 -> 0.25828829 | I52: =I51/I$7 -> 0.2828246 | J52: =J51/J$7 -> 0.29702066 | K52: =K51/K$7 -> 0.3029002 | L52: =L51/L$7 -> 0.30604317 | M52: =M51/M$7 -> 0.30819486 | ... O52: =O51/O$7 -> 0.30956303
B54: 10 | D54: Tax Expenses | F54: =MAX(0,F51*$Q$54) -> 0 | G54: =MAX(0,G51*$Q$54) -> 131.47554 | H54: =MAX(0,SUM(F51:H51)*$Q$54) -> 417.49898 | I54: =MAX(0,SUM(F51:I51)-262.85)*$Q$54 -> 842.81432 | J54: =MAX(0,(J51-149.33)*$Q$54) -> 728.90861 | K54: =MAX(0,K51*$Q$54) -> 1026.3937 | L54: =MAX(0,L51*$Q$54) -> 1317.5098 | M54: =MAX(0,M51*$Q$54) -> 1672.7943 | N54: =MAX(0,N51*$Q$54) -> 2088.037 | O54: =MAX(0,O51*$Q$54) -> 2574.4977 | Q54: 0.3
B56: 11 | D56: PAT [10-11] | F56: =F51-F54 -> -32.216659 | G56: =G51-G54 -> 306.77627 | H56: =H51-H54 -> 568.12913 | I56: =I51-I54 -> 837.75348 | J56: =J51-J54 -> 1850.1168 | K56: =K51-K54 -> 2394.9187 | L56: =L51-L54 -> 3074.1895 | M56: =M51-M54 -> 3903.1868 | ... O56: =O51-O54 -> 6007.1613
D57: PAT % | F57: =F56/F$7 -> -0.051137554 | G57: =G56/G$7 -> 0.14242167 | H57: =H56/H$7 -> 0.1488808 | I57: =I56/I$7 -> 0.14098645 | J57: =J56/J$7 -> 0.21307386 | K57: =K56/K$7 -> 0.21203014 | L57: =L56/L$7 -> 0.21423022 | M57: =M56/M$7 -> 0.2157364 | ... O57: =O56/O$7 -> 0.21669412

Sheet CFS
D2: As Per BS | F2: =BS!F51 -> 2738.0139 | G2: =BS!G51 -> 2701.5729 | H2: =BS!H51 -> 3054.1694 | I2: =BS!I51 -> 3732.0171 | J2: =BS!J51 -> 4784.7245 | K2: =BS!K51 -> 6797.4835 | L2: =BS!L51 -> 9440.7406 | M2: =BS!M51 -> 12881.013 | ... O2: =BS!O51 -> 22614.27
D3: Check | F3: =F2-F58 -> 0 | G3: =G2-G58 -> 0 | H3: =H2-H58 -> 0 | I3: =I2-I58 -> 0 | J3: =J2-J58 -> 0 | K3: =K2-K58 -> 0 | L3: =L2-L58 -> 0 | M3: =M2-M58 -> 0 | ... O3: =O2-O58 -> 0
B5: Cash Flow Statement
O6: =Do -> (₹ in Lakhs)
B8: SI No. | D8: Particulars | F8: =BS!F7 -> 25-26 | G8: =BS!G7 -> 26-27 | H8: =BS!H7 -> 27-28 | I8: =BS!I7 -> 28-29 | J8: =BS!J7 -> 29-30 | K8: =BS!K7 -> 30-31 | L8: =BS!L7 -> 31-32 | M8: =BS!M7 -> 32-33 | ... O8: =BS!O7 -> 34-35
B10: A. Operating Activities
B12: 1 | D12: Net Profit After Tax | F12: ='P&L'!F56 -> -32.216659 | G12: ='P&L'!G56 -> 306.77627 | H12: ='P&L'!H56 -> 568.12913 | I12: ='P&L'!I56 -> 837.75348 | J12: ='P&L'!J56 -> 1850.1168 | K12: ='P&L'!K56 -> 2394.9187 | L12: ='P&L'!L56 -> 3074.1895 | M12: ='P&L'!M56 -> 3903.1868 | ... O12: ='P&L'!O56 -> 6007.1613
B14: 2 | D14: Adjustments to net profits
B16: 2.1 | D16: Depreciation & Amortisation | F16: ='P&L'!F44 -> 37.351708 | G16: ='P&L'!G44 -> 39.852912 | H16: ='P&L'!H44 -> 44.969264 | I16: ='P&L'!I44 -> 53.665192 | J16: ='P&L'!J44 -> 62.148476 | K16: ='P&L'!K44 -> 69.252604 | L16: ='P&L'!L44 -> 81.864079 | M16: ='P&L'!M44 -> 92.253211 | ... O16: ='P&L'!O44 -> 126.01992
B18: 2.2 | D18: Finance Cost | F18: ='P&L'!F49 -> 179.66495 | G18: ='P&L'!G49 -> 173.67528 | H18: ='P&L'!H49 -> 167.01762 | I18: ='P&L'!I49 -> 159.61466 | J18: ='P&L'!J49 -> 151.37989 | K18: ='P&L'!K49 -> 142.31144 | L18: ='P&L'!L49 -> 135.77614 | M18: ='P&L'!M49 -> 132.7635 | ... O18: ='P&L'!O49 -> 125.917
B20: 2.3 | D20: Movement in Working Capital | F20: =BS!F79+BS!F81+BS!F83 -> -68.307524 | G20: =BS!G79+BS!G81+BS!G83 -> -203.55863 | H20: =BS!H79+BS!H81+BS!H83 -> -206.57445 | I20: =BS!I79+BS!I81+BS!I83 -> -257.53465 | J20: =BS!J79+BS!J81+BS!J83 -> -337.33456 | K20: =BS!K79+BS!K81+BS!K83 -> -319.86171 | L20: =BS!L79+BS!L81+BS!L83 -> -379.14755 | M20: =BS!M79+BS!M81+BS!M83 -> -467.46615 | ... O20: =BS!O79+BS!O81+BS!O83 -> -670.2602
B22: 2.4 | D22: Tax Provision | F22: =-BS!F29 -> 0 | G22: =-BS!F29+BS!G29 -> 131.47554 | H22: =-BS!G29+BS!H29 -> 286.02344 | I22: =-BS!H29+BS!I29 -> 425.31534 | J22: =-BS!I29+BS!J29 -> -113.90571 | K22: =-BS!J29+BS!K29 -> 297.48514 | L22: =-BS!K29+BS!L29 -> 291.11605 | M22: =-BS!L29+BS!M29 -> 355.28454 | N22: =-BS!M29+BS!N29 -> 415.24268 | O22: =-BS!N29+BS!O29 -> 486.46069
D24: Cash flows from Operating Activities | F24: =SUM(F12:F22) -> 116.49248 | G24: =SUM(G12:G22) -> 448.22137 | H24: =SUM(H12:H22) -> 859.565 | I24: =SUM(I12:I22) -> 1218.814 | J24: =SUM(J12:J22) -> 1612.4049 | K24: =SUM(K12:K22) -> 2584.1062 | L24: =SUM(L12:L22) -> 3203.7982 | M24: =SUM(M12:M22) -> 4016.0219 | ... O24: =SUM(O12:O22) -> 6075.2987
B28: B. Financing Activities
B30: 3 | D30: Promoters contribution | F30: =Config!C15 -> 300
B32: 4 | D32: Term loans & Borrowings | F32: ='Debt Schedule'!C73 -> 2774.16 | G32: ='Debt Schedule'!D73 -> 0 | H32: ='Debt Schedule'!E73 -> 0 | I32: ='Debt Schedule'!F73 -> 0 | J32: ='Debt Schedule'!G73 -> 0 | K32: ='Debt Schedule'!H73 -> 0 | L32: ='Debt Schedule'!I73 -> 0 | M32: ='Debt Schedule'!J73 -> 0 | ... O32: ='Debt Schedule'!L73 -> 0
B34: 5 | D34: Loan repayment | F34: =-('Debt Schedule'!C65) -> -230.34335 | G34: =-('Debt Schedule'!D65) -> -246.98709 | H34: =-('Debt Schedule'!E65) -> -264.95088 | I34: =-('Debt Schedule'!F65) -> -284.3516 | J34: =-('Debt Schedule'!G65) -> -305.31765 | K34: =-('Debt Schedule'!H65) -> -326.03574 | L34: =-('Debt Schedule'!I65) -> -284.76501 | M34: =-('Debt Schedule'!J65) -> -302.98637 | ... O34: =-('Debt Schedule'!L65) -> -343.08801
B36: 6 | D36: Interest Repayment | F36: =-F18 -> -179.66495 | G36: =-G18 -> -173.67528 | H36: =-H18 -> -167.01762 | I36: =-I18 -> -159.61466 | J36: =-J18 -> -151.37989 | K36: =-K18 -> -142.31144 | L36: =-L18 -> -135.77614 | M36: =-M18 -> -132.7635 | ... O36: =-O18 -> -125.917
D38: Cash flows from Financing Activities | F38: =SUM(F30:F36) -> 2664.1517 | G38: =SUM(G30:G36) -> -420.66236 | H38: =SUM(H30:H36) -> -431.9685 | I38: =SUM(I30:I36) -> -443.96626 | J38: =SUM(J30:J36) -> -456.69755 | K38: =SUM(K30:K36) -> -468.34717 | L38: =SUM(L30:L36) -> -420.54115 | M38: =SUM(M30:M36) -> -435.74987 | ... O38: =SUM(O30:O36) -> -469.00501
B42: C. Investing Activities
B44: 7 | D44: Acquisition of fixed assets | F44: =-DAS!F83 -> -43 | G44: =-DAS!H83 -> -64 | H44: =-DAS!J83 -> -75 | I44: =-DAS!L83 -> -97 | J44: =-DAS!N83 -> -103 | K44: =-DAS!P83 -> -103 | L44: =-DAS!R83 -> -140 | M44: =-DAS!T83 -> -140 | N44: =-DAS!V83 -> -165 | O44: =-DAS!X83 -> -220
B46: 8 | D46: Disposal of fixed assets | F46: 0 | G46: 0 | H46: 0 | I46: 0 | J46: 0 | K46: 0 | L46: 0 | M46: 0 | N46: 0 | O46: 0
B48: 9 | D48: Movement in other non-current assets | F48: 0 | G48: 0 | H48: 0 | I48: 0 | J48: 0 | K48: 0 | L48: 0 | M48: 0 | N48: 0 | O48: 0
D50: Cash flows from Investing Activities | F50: =SUM(F44:F48) -> -43 | G50: =SUM(G44:G48) -> -64 | H50: =SUM(H44:H48) -> -75 | I50: =SUM(I44:I48) -> -97 | J50: =SUM(J44:J48) -> -103 | K50: =SUM(K44:K48) -> -103 | L50: =SUM(L44:L48) -> -140 | M50: =SUM(M44:M48) -> -140 | ... O50: =SUM(O44:O48) -> -220
D54: Net cash flows from all activities | F54: =F24+F38+F50 -> 2737.6442 | G54: =G24+G38+G50 -> -36.440992 | H54: =H24+H38+H50 -> 352.5965 | I54: =I24+I38+I50 -> 677.84776 | J54: =J24+J38+J50 -> 1052.7073 | K54: =K24+K38+K50 -> 2012.759 | L54: =L24+L38+L50 -> 2643.2571 | M54: =M24+M38+M50 -> 3440.272 | ... O54: =O24+O38+O50 -> 5386.2937
D56: Opening cash balance | F56: =Config!C8 -> 0.3696979 | G56: =F58 -> 2738.0139 | H56: =G58 -> 2701.5729 | I56: =H58 -> 3054.1694 | J56: =I58 -> 3732.0171 | K56: =J58 -> 4784.7245 | L56: =K58 -> 6797.4835 | M56: =L58 -> 9440.7406 | N56: =M58 -> 12881.013 | O56: =N58 -> 17227.976
D58: Closing cash balance | F58: =F56+F54 -> 2738.0139 | G58: =G56+G54 -> 2701.5729 | H58: =H56+H54 -> 3054.1694 | I58: =I56+I54 -> 3732.0171 | J58: =J56+J54 -> 4784.7245 | K58: =K56+K54 -> 6797.4835 | L58: =L56+L54 -> 9440.7406 | M58: =M56+M54 -> 12881.013 | ... O58: =O56+O54 -> 22614.27

Sheet Revenue generation breakup
B2: Summary of Revenue
B5: Revenue Generation Breakup ( Lakhs) | J5: Revenue, Expenses and Profit _Generation Breakup ( Lakhs)
B6: SL.No | C6: Year | D6: Corporate Sales | E6: Millet Cafeterias | F6: Retail Market Sales | G6: Exports | H6: Total Revenue | J6: SL.No | K6: Year | L6: Corporate Snacks- Revenue | M6: Expenses | N6: Gross Profit | O6: Gross Profit% | P6: Millet Cafeterias-Revenue | Q6: Expenses | R6: Gross Profit | S6: Gross Profit% | T6: Retail Market -Revenue | U6: Expenses | V6: Gross Profit | W6: Gross Profit% | X6: Exports -Revenue | Y6: Expenses | Z6: Gross Profit | AA6: Gross Profit% | AB6: Total Revenue | AC6: Total Expenses | AD6: Total Gross Profit
B7: 1 | C7: 2025 | D7: ='Revenue generation breakup'!I23 -> 135 | E7: ='Revenue generation breakup'!F50 -> 270 | F7: ='Revenue generation breakup'!E65 -> 75 | G7: ='Revenue generation breakup'!E81 -> 150 | H7: =SUM(D7:G7) -> 630 | J7: 1 | K7: 2025 | L7: =D7 -> 135 | M7: =L7*0.75 -> 101.25 | N7: =L7-M7 -> 33.75 | O7: =(L7-M7)/L7 -> 0.25 | P7: =E7 -> 270 | Q7: =P7*60% -> 162 | R7: =P7-Q7 -> 108 | S7: =(P7-Q7)/P7 -> 0.4 | T7: =F7 -> 75 | U7: =T7*78% -> 58.5 | V7: =T7-U7 -> 16.5 | W7: =(T7-U7)/T7 -> 0.22 | X7: =G7 -> 150 | Y7: =X7*65% -> 97.5 | Z7: =X7-Y7 -> 52.5 | AA7: =(X7-Y7)/X7 -> 0.35 | AB7: =L7+P7+T7+X7 -> 630 | AC7: =M7+Q7+U7+Y7 -> 419.25 | AD7: =N7+R7+V7+Z7 -> 210.75
B8: 2 | C8: 2026 | D8: ='Revenue generation breakup'!I24 -> 162 | E8: ='Revenue generation breakup'!F51 -> 792 | F8: ='Revenue generation breakup'!E66 -> 600 | G8: ='Revenue generation breakup'!E82 -> 600 | H8: =SUM(D8:G8) -> 2154 | J8: 2 | K8: 2026 | L8: =D8 -> 162 | M8: =L8*0.75 -> 121.5 | N8: =L8-M8 -> 40.5 | O8: =(L8-M8)/L8 -> 0.25 | P8: =E8 -> 792 | Q8: =P8*60% -> 475.2 | R8: =P8-Q8 -> 316.8 | S8: =(P8-Q8)/P8 -> 0.4 | T8: =F8 -> 600 | U8: =T8*78% -> 468 | V8: =T8-U8 -> 132 | W8: =(T8-U8)/T8 -> 0.22 | X8: =G8 -> 600 | Y8: =X8*65% -> 390 | Z8: =X8-Y8 -> 210 | AA8: =(X8-Y8)/X8 -> 0.35 | AB8: =L8+P8+T8+X8 -> 2154 | AC8: =M8+Q8+U8+Y8 -> 1454.7 | AD8: =N8+R8+V8+Z8 -> 699.3
B9: 3 | C9: 2027 | D9: ='Revenue generation breakup'!I25 -> 202.5 | E9: ='Revenue generation breakup'!F52 -> 1633.5 | F9: ='Revenue generation breakup'!E67 -> 1200 | G9: ='Revenue generation breakup'!E83 -> 780 | H9: =SUM(D9:G9) -> 3816 | J9: 3 | K9: 2027 | L9: =D9 -> 202.5 | M9: =L9*0.75 -> 151.875 | N9: =L9-M9 -> 50.625 | O9: =(L9-M9)/L9 -> 0.25 | P9: =E9 -> 1633.5 | Q9: =P9*60% -> 980.1 | R9: =P9-Q9 -> 653.4 | S9: =(P9-Q9)/P9 -> 0.4 | T9: =F9 -> 1200 | U9: =T9*78% -> 936 | V9: =T9-U9 -> 264 | W9: =(T9-U9)/T9 -> 0.22 | X9: =G9 -> 780 | Y9: =X9*65% -> 507 | Z9: =X9-Y9 -> 273 | AA9: =(X9-Y9)/X9 -> 0.35 | AB9: =L9+P9+T9+X9 -> 3816 | AC9: =M9+Q9+U9+Y9 -> 2574.975 | AD9: =N9+R9+V9+Z9 -> 1241.025
B10: 4 | C10: 2028 | D10: ='Revenue generation breakup'!I26 -> 253.125 | E10: ='Revenue generation breakup'!F53 -> 2874.96 | F10: ='Revenue generation breakup'!E68 -> 1800 | G10: ='Revenue generation breakup'!E84 -> 1014 | H10: =SUM(D10:G10) -> 5942.085 | J10: 4 | K10: 2028 | L10: =D10 -> 253.125 | M10: =L10*0.75 -> 189.84375 | N10: =L10-M10 -> 63.28125 | O10: =(L10-M10)/L10 -> 0.25 | P10: =E10 -> 2874.96 | Q10: =P10*60% -> 1724.976 | R10: =P10-Q10 -> 1149.984 | S10: =(P10-Q10)/P10 -> 0.4 | T10: =F10 -> 1800 | U10: =T10*78% -> 1404 | V10: =T10-U10 -> 396 | W10: =(T10-U10)/T10 -> 0.22 | X10: =G10 -> 1014 | Y10: =X10*65% -> 659.1 | Z10: =X10-Y10 -> 354.9 | AA10: =(X10-Y10)/X10 -> 0.35 | AB10: =L10+P10+T10+X10 -> 5942.085 | AC10: =M10+Q10+U10+Y10 -> 3977.9198 | AD10: =N10+R10+V10+Z10 -> 1964.1653
B11: 5 | C11: 2029 | D11: ='Revenue generation breakup'!I27 -> 316.40625 | E11: ='Revenue generation breakup'!F54 -> 4348.377 | F11: ='Revenue generation breakup'!E69 -> 2700 | G11: ='Revenue generation breakup'!E85 -> 1318.2 | H11: =SUM(D11:G11) -> 8682.9833 | J11: 5 | K11: 2029 | L11: =D11 -> 316.40625 | M11: =L11*0.75 -> 237.30469 | N11: =L11-M11 -> 79.101562 | O11: =(L11-M11)/L11 -> 0.25 | P11: =E11 -> 4348.377 | Q11: =P11*60% -> 2609.0262 | R11: =P11-Q11 -> 1739.3508 | S11: =(P11-Q11)/P11 -> 0.4 | T11: =F11 -> 2700 | U11: =T11*78% -> 2106 | V11: =T11-U11 -> 594 | W11: =(T11-U11)/T11 -> 0.22 | X11: =G11 -> 1318.2 | Y11: =X11*65% -> 856.83 | Z11: =X11-Y11 -> 461.37 | AA11: =(X11-Y11)/X11 -> 0.35 | AB11: =L11+P11+T11+X11 -> 8682.9833 | AC11: =M11+Q11+U11+Y11 -> 5809.1609 | AD11: =N11+R11+V11+Z11 -> 2873.8224
B12: 6 | C12: 2030 | D12: ='Revenue generation breakup'!I28 -> 395.50781 | E12: ='Revenue generation breakup'!F55 -> 5811.0129 | F12: ='Revenue generation breakup'!E70 -> 3375 | G12: ='Revenue generation breakup'!E86 -> 1713.66 | H12: =SUM(D12:G12) -> 11295.181 | J12: 6 | K12: 2030 | L12: =D12 -> 395.50781 | M12: =L12*0.75 -> 296.63086 | N12: =L12-M12 -> 98.876953 | O12: =(L12-M12)/L12 -> 0.25 | P12: =E12 -> 5811.0129 | Q12: =P12*60% -> 3486.6077 | R12: =P12-Q12 -> 2324.4052 | S12: =(P12-Q12)/P12 -> 0.4 | T12: =F12 -> 3375 | U12: =T12*78% -> 2632.5 | V12: =T12-U12 -> 742.5 | W12: =(T12-U12)/T12 -> 0.22 | X12: =G12 -> 1713.66 | Y12: =X12*65% -> 1113.879 | Z12: =X12-Y12 -> 599.781 | AA12: =(X12-Y12)/X12 -> 0.35 | AB12: =L12+P12+T12+X12 -> 11295.181 | AC12: =M12+Q12+U12+Y12 -> 7529.6176 | AD12: =N12+R12+V12+Z12 -> 3765.5631
B13: 7 | C13: 2031 | D13: ='Revenue generation breakup'!I29 -> 494.38477 | E13: ='Revenue generation breakup'!F56 -> 7409.0414 | F13: ='Revenue generation breakup'!E71 -> 4218.75 | G13: ='Revenue generation breakup'!E87 -> 2227.758 | H13: =SUM(D13:G13) -> 14349.934 | J13: 7 | K13: 2031 | L13: =D13 -> 494.38477 | M13: =L13*0.75 -> 370.78857 | N13: =L13-M13 -> 123.59619 | O13: =(L13-M13)/L13 -> 0.25 | P13: =E13 -> 7409.0414 | Q13: =P13*60% -> 4445.4249 | R13: =P13-Q13 -> 2963.6166 | S13: =(P13-Q13)/P13 -> 0.4 | T13: =F13 -> 4218.75 | U13: =T13*78% -> 3290.625 | V13: =T13-U13 -> 928.125 | W13: =(T13-U13)/T13 -> 0.22 | X13: =G13 -> 2227.758 | Y13: =X13*65% -> 1448.0427 | Z13: =X13-Y13 -> 779.7153 | AA13: =(X13-Y13)/X13 -> 0.35 | AB13: =L13+P13+T13+X13 -> 14349.934 | AC13: =M13+Q13+U13+Y13 -> 9554.8811 | AD13: =N13+R13+V13+Z13 -> 4795.0531
B14: 8 | C14: 2032 | D14: ='Revenue generation breakup'!I30 -> 617.98096 | E14: ='Revenue generation breakup'!F57 -> 9304.8844 | F14: ='Revenue generation breakup'!E72 -> 5273.4375 | G14: ='Revenue generation breakup'!E88 -> 2896.0854 | H14: =SUM(D14:G14) -> 18092.388 | J14: 8 | K14: 2032 | L14: =D14 -> 617.98096 | M14: =L14*0.75 -> 463.48572 | N14: =L14-M14 -> 154.49524 | O14: =(L14-M14)/L14 -> 0.25 | P14: =E14 -> 9304.8844 | Q14: =P14*60% -> 5582.9306 | R14: =P14-Q14 -> 3721.9538 | S14: =(P14-Q14)/P14 -> 0.4 | T14: =F14 -> 5273.4375 | U14: =T14*78% -> 4113.2812 | V14: =T14-U14 -> 1160.1562 | W14: =(T14-U14)/T14 -> 0.22 | X14: =G14 -> 2896.0854 | Y14: =X14*65% -> 1882.4555 | Z14: =X14-Y14 -> 1013.6299 | AA14: =(X14-Y14)/X14 -> 0.35 | AB14: =L14+P14+T14+X14 -> 18092.388 | AC14: =M14+Q14+U14+Y14 -> 12042.153 | AD14: =N14+R14+V14+Z14 -> 6050.2351
B15: 9 | C15: 2033 | D15: ='Revenue generation breakup'!I31 -> 772.4762 | E15: ='Revenue generation breakup'!F58 -> 11371.789 | F15: ='Revenue generation breakup'!E73 -> 6591.7969 | G15: ='Revenue generation breakup'!E89 -> 3764.911 | H15: =SUM(D15:G15) -> 22500.973 | J15: 9 | K15: 2033 | L15: =D15 -> 772.4762 | M15: =L15*0.75 -> 579.35715 | N15: =L15-M15 -> 193.11905 | O15: =(L15-M15)/L15 -> 0.25 | P15: =E15 -> 11371.789 | Q15: =P15*60% -> 6823.0734 | R15: =P15-Q15 -> 4548.7156 | S15: =(P15-Q15)/P15 -> 0.4 | T15: =F15 -> 6591.7969 | U15: =T15*78% -> 5141.6016 | V15: =T15-U15 -> 1450.1953 | W15: =(T15-U15)/T15 -> 0.22 | X15: =G15 -> 3764.911 | Y15: =X15*65% -> 2447.1922 | Z15: =X15-Y15 -> 1317.7189 | AA15: =(X15-Y15)/X15 -> 0.35 | AB15: =L15+P15+T15+X15 -> 22500.973 | AC15: =M15+Q15+U15+Y15 -> 14991.224 | AD15: =N15+R15+V15+Z15 -> 7509.7488
B16: 10 | C16: 2034 | D16: ='Revenue generation breakup'!I32 -> 965.59525 | E16: ='Revenue generation breakup'!F59 -> 13622.122 | F16: ='Revenue generation breakup'!E74 -> 8239.7461 | G16: ='Revenue generation breakup'!E90 -> 4894.3843 | H16: =SUM(D16:G16) -> 27721.848 | J16: 10 | K16: 2034 | L16: =D16 -> 965.59525 | M16: =L16*0.75 -> 724.19643 | N16: =L16-M16 -> 241.39881 | O16: =(L16-M16)/L16 -> 0.25 | P16: =E16 -> 13622.122 | Q16: =P16*60% -> 8173.2732 | R16: =P16-Q16 -> 5448.8488 | S16: =(P16-Q16)/P16 -> 0.4 | T16: =F16 -> 8239.7461 | U16: =T16*78% -> 6427.002 | V16: =T16-U16 -> 1812.7441 | W16: =(T16-U16)/T16 -> 0.22 | X16: =G16 -> 4894.3843 | Y16: =X16*65% -> 3181.3498 | Z16: =X16-Y16 -> 1713.0345 | AA16: =(X16-Y16)/X16 -> 0.35 | AB16: =L16+P16+T16+X16 -> 27721.848 | AC16: =M16+Q16+U16+Y16 -> 18505.821 | AD16: =N16+R16+V16+Z16 -> 9216.0263
D17: =SUM(D7:D16) -> 4314.9762 | E17: =SUM(E7:E16) -> 57437.687 | F17: =SUM(F7:F16) -> 34073.73 | G17: =SUM(G7:G16) -> 19358.999 | H17: =SUM(H7:H16) -> 115185.39 | L17: =SUM(L7:L16) -> 4314.9762 | P17: =SUM(P7:P16) -> 57437.687 | T17: =SUM(T7:T16) -> 34073.73 | X17: =SUM(X7:X16) -> 19358.999 | AB17: =SUM(AB7:AB16) -> 115185.39 | AC17: =SUM(AC7:AC16) -> 76859.703 | AD17: =SUM(AD7:AD16) -> 38325.689
B19: Corporate Sales
K21: Operational Cost Breakup
B22: SL.No | C22: Year | D22: Average Clients Acquizition per month 4 Clients ( with growth of 25% year on year) | E22: Client Retention Ration 60% | F22: Average Product sales price to Client (INR) with increase of price 5% year on year | G22: Average Product Sales per Client 75000 per Month | H22: Average Product Sales per Client Annum | I22: Revenue in Lakhs | K22: SL.No | L22: Operation Head | M22: Expenses ratio on total revenue generation | N22: Remarks
B23: 1 | C23: 2025 | D23: 25 | E23: =D23*60% -> 15 | F23: 35 | G23: =75000*E23 -> 1125000 | H23: =G23*12 -> 13500000 | I23: =H23/100000 -> 135 | K23: 1 | L23: RM &Packing cost with Packing | M23: 0.35 | N23: Fixed, incraeses 5% year on year
B24: 2 | C24: 2026 | D24: =24*125% -> 30 | E24: =D24*60% -> 18 | F24: =F23*105% -> 36.75 | G24: =75000*E24 -> 1350000 | H24: =G24*12 -> 16200000 | I24: =H24/100000 -> 162 | K24: 2 | L24: Employee salaries | M24: 0.25 | N24: Every Employee handles 5 clients
B25: 3 | C25: 2027 | D25: =D24*125% -> 37.5 | E25: =D25*60% -> 22.5 | F25: =F24*105% -> 38.5875 | G25: =75000*E25 -> 1687500 | H25: =G25*12 -> 20250000 | I25: =H25/100000 -> 202.5 | K25: 3 | L25: Promotional expenses | M25: 0.05 | N25: Fixed, increase 5% year on year
B26: 4 | C26: 2028 | D26: =D25*125% -> 46.875 | E26: =D26*60% -> 28.125 | F26: =F25*105% -> 40.516875 | G26: =75000*E26 -> 2109375 | H26: =G26*12 -> 25312500 | I26: =H26/100000 -> 253.125 | K26: 4 | L26: Other expenses | M26: 0.1 | N26: Fixed, increase 5% year on year
B27: 5 | C27: 2029 | D27: =D26*125% -> 58.59375 | E27: =D27*60% -> 35.15625 | F27: =F26*105% -> 42.542719 | G27: =75000*E27 -> 2636718.8 | H27: =G27*12 -> 31640625 | I27: =H27/100000 -> 316.40625 | L27: Total Expenses on product price | M27: =SUM(M23:M26) -> 0.75
B28: 6 | C28: 2030 | D28: =D27*125% -> 73.242188 | E28: =D28*60% -> 43.945312 | F28: =F27*105% -> 44.669855 | G28: =75000*E28 -> 3295898.4 | H28: =G28*12 -> 39550781 | I28: =H28/100000 -> 395.50781
B29: 7 | C29: 2031 | D29: =D28*125% -> 91.552734 | E29: =D29*60% -> 54.931641 | F29: =F28*105% -> 46.903347 | G29: =75000*E29 -> 4119873 | H29: =G29*12 -> 49438477 | I29: =H29/100000 -> 494.38477
B30: 8 | C30: 2032 | D30: =D29*125% -> 114.44092 | E30: =D30*60% -> 68.664551 | F30: =F29*105% -> 49.248515 | G30: =75000*E30 -> 5149841.3 | H30: =G30*12 -> 61798096 | I30: =H30/100000 -> 617.98096
B31: 9 | C31: 2033 | D31: =D30*125% -> 143.05115 | E31: =D31*60% -> 85.830688 | F31: =F30*105% -> 51.710941 | G31: =75000*E31 -> 6437301.6 | H31: =G31*12 -> 77247620 | I31: =H31/100000 -> 772.4762
B32: 10 | C32: 2034 | D32: =D31*125% -> 178.81393 | E32: =D32*60% -> 107.28836 | F32: =F31*105% -> 54.296488 | G32: =75000*E32 -> 8046627 | H32: =G32*12 -> 96559525 | I32: =H32/100000 -> 965.59525
C33: Total | D33: =SUM(D23:D32) -> 799.06967 | E33: =SUM(E23:E32) -> 479.4418 | I33: =SUM(I23:I32) -> 4314.9762
B35: Millet Cafeteria
B37: SL.No | C37: Reveune genertaion from Millet Cafeteria | D37: Breakup (in Lakhs/Annum) | E37: Remarks | G37: Breakup for Revenue Generation fo 125 Lakhs
B38: 1 | C38: Revenue generation per cafeteria | D38: 90 | E38: 10% growth in revenue genertaion year on year for first 5 years and later 5 % growth year on year | G38: Cost of Items | H38: INR | I38: No of Plates Sales/day | J38: No. of Hours Operations | K38: Per hour Plates sales target | L38: Revenue Generation/day | M38: No.of working days in Month 25 days | N38: Revenue generation/Annum | O38: Revenue generation with consideration of 65% achievement of target | P38: Revenue in lakhs
B39: 2 | C39: Expenses Heads | G39: Average Breakfast Cost for Morning | H39: 75 | I39: 300 | J39: 5 | K39: =I39/J39 -> 60 | L39: =I39*H39 -> 22500 | M39: =L39*25 -> 562500 | N39: =M39*12 -> 6750000 | O39: =N39*65% -> 4387500 | P39: =O39/100000 -> 43.875
B40: 2.1 | C40: RM Cost | D40: =D38*22% -> 19.8 | E40: 8% increase of RM cost year on Year | G40: Average Meals/Thali Cost for Afternoon | H40: 110 | I40: 270 | J40: 4 | K40: =I40/J40 -> 67.5 | L40: =I40*H40 -> 29700 | M40: =L40*25 -> 742500 | N40: =M40*12 -> 8910000 | O40: =N40*65% -> 5791500 | P40: =O40/100000 -> 57.915
B41: 2.2 | C41: Cook and Staff Salaries | D41: =D38*25% -> 22.5 | E41: 10% increase of RM cost year on Year | G41: Average snacks cost for Evening | H41: 60 | I41: 200 | J41: 4 | K41: =I41/J41 -> 50 | L41: =I41*H41 -> 12000 | M41: =L41*25 -> 300000 | N41: =M41*12 -> 3600000 | O41: =N41*65% -> 2340000 | P41: =O41/100000 -> 23.4
B42: 2.3 | C42: Cafeteria Rent | D42: =D38*10% -> 9 | E42: 7% increase of RM cost year on Year | G42: Total | I42: =SUM(I39:I41) -> 770 | J42: =SUM(J39:J41) -> 13 | K42: =SUM(K39:K41) -> 177.5 | L42: =SUM(L39:L41) -> 64200 | M42: =SUM(M39:M41) -> 1605000 | N42: =SUM(N39:N41) -> 19260000 | O42: =SUM(O39:O41) -> 12519000 | P42: =O42/100000 -> 125.19
B43: 2.4 | C43: Miscelanous Expenses | D43: =D38*4% -> 3.6 | E43: 5% increase of RM cost year on Year
B44: 2.5 | C44: Promotional Expenses | D44: =D38*5% -> 4.5 | E44: 10% increase of RM cost year on Year
B45: 3 | C45: Total Expenses | D45: =SUM(D40:D44) -> 59.4
B46: 4 | C46: Gross Profit | D46: =D38-D45 -> 30.6
B47: 4.1 | C47: Gross Profit % | D47: =D46/D38 -> 0.34
...

Sheet All Costs
D3: Assessment of All Costs (in Lakhs)
B6: SI No. | D6: Sales | E6: ='P&L'!F5 -> 2025-26 | F6: ='P&L'!G5 -> 2026-27 | G6: ='P&L'!H5 -> 2027-28 | H6: ='P&L'!I5 -> 2028-29 | I6: ='P&L'!J5 -> 2029-30 | J6: ='P&L'!K5 -> 2030-31 | K6: ='P&L'!L5 -> 2031-32 | L6: ='P&L'!M5 -> 2032-33 | ... N6: ='P&L'!O5 -> 2034-35
B7: 1 | D7: Corporate Sales | E7: ='P&L'!F9 -> 135 | F7: ='P&L'!G9 -> 162 | G7: ='P&L'!H9 -> 202.5 | H7: ='P&L'!I9 -> 253.125 | I7: ='P&L'!J9 -> 316.40625 | J7: ='P&L'!K9 -> 395.50781 | K7: ='P&L'!L9 -> 494.38477 | L7: ='P&L'!M9 -> 617.98096 | ... N7: ='P&L'!O9 -> 965.59525
B8: 2 | D8: Millet Cafeteria | E8: ='P&L'!F11 -> 270 | F8: ='P&L'!G11 -> 792 | G8: ='P&L'!H11 -> 1633.5 | H8: ='P&L'!I11 -> 2874.96 | I8: ='P&L'!J11 -> 4348.377 | J8: ='P&L'!K11 -> 5811.0129 | K8: ='P&L'!L11 -> 7409.0414 | L8: ='P&L'!M11 -> 9304.8844 | ... N8: ='P&L'!O11 -> 13622.122
B9: 3 | D9: Retail Market Sales | E9: ='P&L'!F13 -> 75 | F9: ='P&L'!G13 -> 600 | G9: ='P&L'!H13 -> 1200 | H9: ='P&L'!I13 -> 1800 | I9: ='P&L'!J13 -> 2700 | J9: ='P&L'!K13 -> 3375 | K9: ='P&L'!L13 -> 4218.75 | L9: ='P&L'!M13 -> 5273.4375 | ... N9: ='P&L'!O13 -> 8239.7461
B10: 4 | D10: Export Sales | E10: ='P&L'!F15 -> 150 | F10: ='P&L'!G15 -> 600 | G10: ='P&L'!H15 -> 780 | H10: ='P&L'!I15 -> 1014 | I10: ='P&L'!J15 -> 1318.2 | J10: ='P&L'!K15 -> 1713.66 | K10: ='P&L'!L15 -> 2227.758 | L10: ='P&L'!M15 -> 2896.0854 | ... N10: ='P&L'!O15 -> 4894.3843
B12: SI No. | D12: Direct Costs | E12: =E6 -> 2025-26 | F12: =F6 -> 2026-27 | G12: =G6 -> 2027-28 | H12: =H6 -> 2028-29 | I12: =I6 -> 2029-30 | J12: =J6 -> 2030-31 | K12: =K6 -> 2031-32 | L12: =L6 -> 2032-33 | ... N12: =N6 -> 2034-35
B13: 1 | D13: Direct Cost % ( % of Corporate Sales ) | E13: ='Revenue generation breakup'!M23 -> 0.35 | F13: =E13 -> 0.35 | G13: =F13 -> 0.35 | H13: =G13 -> 0.35 | I13: =H13 -> 0.35 | J13: =I13 -> 0.35 | K13: =J13 -> 0.35 | L13: =K13 -> 0.35 | M13: =L13 -> 0.35 | N13: =M13 -> 0.35
B14: 2 | D14: Direct Cost % ( % of Millet Cafeteria ) | E14: ='Revenue generation breakup'!D40/'Revenue generation breakup'!D38 -> 0.22 | F14: =E14 -> 0.22 | G14: =F14 -> 0.22 | H14: =G14 -> 0.22 | I14: =H14 -> 0.22 | J14: =I14 -> 0.22 | K14: =J14 -> 0.22 | L14: =K14 -> 0.22 | M14: =L14 -> 0.22 | N14: =M14 -> 0.22
B15: 3 | D15: Direct Cost % ( % of Retail Market Sales) | E15: 0.65 | F15: =E15 -> 0.65 | G15: =F15 -> 0.65 | H15: =G15 -> 0.65 | I15: =H15 -> 0.65 | J15: =I15 -> 0.65 | K15: =J15 -> 0.65 | L15: =K15 -> 0.65 | M15: =L15 -> 0.65 | N15: =M15 -> 0.65
B16: 4 | D16: Direct Cost % ( % of Export Sales ) | E16: 0.78 | F16: =E16 -> 0.78 | G16: =F16 -> 0.78 | H16: =G16 -> 0.78 | I16: =H16 -> 0.78 | J16: =I16 -> 0.78 | K16: =J16 -> 0.78 | L16: =K16 -> 0.78 | M16: =L16 -> 0.78 | N16: =M16 -> 0.78
B18: SI No. | D18: Direct Cost | E18: =E6 -> 2025-26 | F18: =F6 -> 2026-27 | G18: =G6 -> 2027-28 | H18: =H6 -> 2028-29 | I18: =I6 -> 2029-30 | J18: =J6 -> 2030-31 | K18: =K6 -> 2031-32 | L18: =L6 -> 2032-33 | ... N18: =N6 -> 2034-35
B19: 1 | D19: Direct Cost (Corporate Sales ) | E19: =E7*E13 -> 47.25 | F19: =F7*F13 -> 56.7 | G19: =G7*G13 -> 70.875 | H19: =H7*H13 -> 88.59375 | I19: =I7*I13 -> 110.74219 | J19: =J7*J13 -> 138.42773 | K19: =K7*K13 -> 173.03467 | L19: =L7*L13 -> 216.29333 | ... N19: =N7*N13 -> 337.95834
B20: =B19+1 -> 2 | D20: Direct Cost ( Millet Cafeteria ) | E20: =E8*E14 -> 59.4 | F20: =F8*F14 -> 174.24 | G20: =G8*G14 -> 359.37 | H20: =H8*H14 -> 632.4912 | I20: =I8*I14 -> 956.64294 | J20: =J8*J14 -> 1278.4228 | K20: =K8*K14 -> 1629.9891 | L20: =L8*L14 -> 2047.0746 | ... N20: =N8*N14 -> 2996.8668
B21: =B20+1 -> 3 | D21: Direct Cost ( Retail Market Sales) | E21: =E9*E15 -> 48.75 | F21: =F9*F15 -> 390 | G21: =G9*G15 -> 780 | H21: =H9*H15 -> 1170 | I21: =I9*I15 -> 1755 | J21: =J9*J15 -> 2193.75 | K21: =K9*K15 -> 2742.1875 | L21: =L9*L15 -> 3427.7344 | ... N21: =N9*N15 -> 5355.835
